Workbook

Sheet REGENERANTS
C1: 2 | D1: 3 | E1: 4 | F1: 5 | G1: 6 | H1: 7 | I1: 8 | J1: 9 | K1: 10 | L1: 11 | M1: 12 | N1: 13 | O1: 14 | P1: 15 | Q1: 16 | R1: 17 | S1: 16 | T1: 17 | Y1: 16 | Z1: 17 | AA1: 18 | AB1: 19 | AC1: 20 | AD1: 21 | AE1: 22 | AF1: 23 | AG1: 24 | AH1: 25 | AI1: 26 | AJ1: 27 | AK1: 28 | AL1: 29 | AM1: 30 | AN1: 31 | AO1: 32 | AP1: 33 | AQ1: 34 | AR1: 35 | AS1: 36 | AT1: 37 | AU1: 38 | AV1: 39 | AW1: 40 | AX1: 41 | AY1: 42 | AZ1: 43 | BA1: 44 | BB1: 45 | BC1: 46 | BD1: 47 | BE1: 48 | BF1: 49 | BG1: 50 | BH1: 51 | BI1: 52 | BJ1: 53 | BK1: 54 | BL1: 55 | BM1: 56 | BN1: 57 | BO1: 58 | BP1: 59 | BQ1: 60 | BR1: 61 | BS1: 62 | BT1: 63 | BU1: 64 | BV1: 65 | BW1: 66 | BX1: 67 | BY1: 68 | BZ1: 69 | CA1: 70 | CB1: 71 | CC1: 72 | CD1: 73 | CE1: 74 | CF1: 75 | CG1: 76 | CH1: 77 | CI1: 78 | CK1: =SUM(CK11:CK370) | DQ1: =SUM(DQ11:DQ317) | DU1: =SUM(DU11:DU370)
H2: =(SUMIF($F$22:$F$62,"<>*PLV*",$H$22:$H$62)*$CF$20)+(SUMIF($F$22:$F$62,"PLV (PDC ou autre)",$H$22:$H$62)*$CJ$20)+(SUMIF($F$22:$F$62,"PLV (vitrine)",$H$22:$H$62)*$CJ$18)+(SUMIF($F$77:$F$98,"<>*PLV*",$H$77:$H$98)*$CF$75)+(SUMIF($F$77:$F$98,"PLV (PDC ou autre)",$H$77:$H$98)*$CJ$75)+(SUMIF($F$77:$F$98,"PLV (vitrine)",$H$77:$H$98)*$CJ$73)+(SUMIF($F$114:$F$153,"<>*PLV*",$H$114:$H$153)*$CF$112)+(SUMIF($F$114:$F$153,"PLV (PDC ou autre)",$H$114:$H$153)*$CJ$112)+(SUMIF($F$114:$F$153,"PLV (vitrine)",$H$114:$H$153)*$CJ$110)+(SUMIF($F$168:$F$207,"<>*PLV*",$H$168:$H$207)*$CF$166)+(SUMIF($F$168:$F$207,"PLV (PDC ou autre)",$H$168:$H$207)*$CJ$166)+(SUMIF($F$168:$F$207,"PLV (vitrine)",$H$168:$H$207)*$CJ$164)+(SUMIF($F$223:$F$262,"<>*PLV*",$H$223:$H$262)*$CF$221)+(SUMIF($F$223:$F$262,"PLV (PDC ou autre)",$H$223:$H$262)*$CJ$221)+(SUMIF($F$223:$F$262,"PLV (vitrine)",$H$223:$H$262)*$CJ$219)+(SUMIF($F$277:$F$316,"<>*PLV*",$H$277:$H$316)*$CF$275)+(SUMIF($F$277:$F$316,"PLV (PDC ou autre)",$H$277:$H$316)*$CJ$275)+(SUMIF($F$277:$F$316,"PLV (vitrine)",$H$277:$H$316)*$CJ$273)+(SUMIF($F$331:$F$370,"<>*PLV*",$H$331:$H$370)*$CF$329)+(SUMIF($F$331:$F$370,"PLV (PDC ou autre)",$H$331:$H$370)*$CJ$329)+(SUMIF($F$331:$F$370,"PLV (vitrine)",$H$331:$H$370)*$CJ$327) | K2: =K20*CF20+K75*CF75+K112*CF112+K166*CF166+K221*CF221+K275*CF275+K329*CF329 | CK2: =IFERROR(H2=CK1,"FAUX") | DU2: =SUMIFS(DU22:DU371,F22:F371,"*PLV*")
K3: =(SUMIFS($K$22:$K$62,$F$22:$F$62,"*PLV*")*$CF$20)+(SUMIFS($K$77:$K$98,$F$77:$F$98,"*PLV*")*$CF$75)+(SUMIFS($K$114:$K$153,$F$114:$F$153,"*PLV*")*$CF$112)+(SUMIFS($K$168:$K$207,$F$168:$F$207,"*PLV*")*$CF$166)+(SUMIFS($K$223:$K$262,$F$223:$F$262,"*PLV*")*$CF$221)+(SUMIFS($K$277:$K$316,$F$277:$F$316,"*PLV*")*$CF$275)+(SUMIFS($K$331:$K$370,$F$331:$F$370,"*PLV*")*$CF$329) | CG3: =SUM(CG8:CG370) | DS3: =SUM(DS8:DS371,DT8:DT371) | DU3: =SUMIFS(DU22:DU371,F22:F371,"Produit Vente")
K4: =(SUMIFS($K$22:$K$62,$F$22:$F$62,"Produit Vente")*$CF$20)+(SUMIFS($K$77:$K$98,$F$77:$F$98,"Produit Vente")*$CF$75)+(SUMIFS($K$114:$K$153,$F$114:$F$153,"Produit Vente")*$CF$112)+(SUMIFS($K$168:$K$207,$F$168:$F$207,"Produit Vente")*$CF$166)+(SUMIFS($K$223:$K$262,$F$223:$F$262,"Produit Vente")*$CF$221)+(SUMIFS($K$277:$K$316,$F$277:$F$316,"Produit Vente")*$CF$275)+(SUMIFS($K$331:$K$370,$F$331:$F$370,"Produit Vente")*$CF$329) | DU4: =SUMIFS(DU22:DU371,F22:F371,"UG")
C5: =MID(CELL("filename",C5),FIND("]",CELL("filename",C5))+1,255) | K5: =(SUMIFS($K$22:$K$62,$F$22:$F$62,"UG")*$CF$20)+(SUMIFS($K$77:$K$98,$F$77:$F$98,"UG")*$CF$75)+(SUMIFS($K$114:$K$153,$F$114:$F$153,"UG")*$CF$112)+(SUMIFS($K$168:$K$207,$F$168:$F$207,"UG")*$CF$166)+(SUMIFS($K$223:$K$262,$F$223:$F$262,"UG")*$CF$221)+(SUMIFS($K$277:$K$316,$F$277:$F$316,"UG")*$CF$275)+(SUMIFS($K$331:$K$370,$F$331:$F$370,"UG")*$CF$329) | DU5: =SUMIFS(DU22:DU371,F22:F371,"Testeur")
C6: ="<<" | K6: =(SUMIFS($K$22:$K$62,$F$22:$F$62,"Testeur")*$CF$20)+(SUMIFS($K$77:$K$98,$F$77:$F$98,"Testeur")*$CF$75)+(SUMIFS($K$114:$K$153,$F$114:$F$153,"Testeur")*$CF$112)+(SUMIFS($K$168:$K$207,$F$168:$F$207,"Testeur")*$CF$166)+(SUMIFS($K$223:$K$262,$F$223:$F$262,"Testeur")*$CF$221)+(SUMIFS($K$277:$K$316,$F$277:$F$316,"Testeur")*$CF$275)+(SUMIFS($K$331:$K$370,$F$331:$F$370,"Testeur")*$CF$329)
CN8: Nbrs Offres planifiées | CO8: CA | CP8: Marges
C9: 670 offres budgétées en 2025 / 457 offres réalisées --> 730 offres en 2026 (+10%) | AB9: 65 | CM9: Retail | CN9: =SUMIFS($AB20:$AT20,$AB17:$AT17,CN8)+SUMIFS($BZ20:$CC20,$BZ17:$CC17,CN8)+SUMIFS($AB75:$AT75,$AB72:$AT72,CN8)+SUMIFS($BZ75:$CC75,$BZ72:$CC72,CN8)+SUMIFS($AB112:$AT112,$AB109:$AT109,CN8)+SUMIFS($BZ112:$CC112,$BZ109:$CC109,CN8)+SUMIFS($AB166:$AT166,$AB163:$AT163,CN8)+SUMIFS($BZ166:$CC166,$BZ163:$CC163,CN8)+SUMIFS($AB221:$AT221,$AB218:$AT218,CN8)+SUMIFS($BZ221:$CC221,$BZ218:$CC218,CN8)+SUMIFS($AB275:$AT275,$AB272:$AT272,CN8)+SUMIFS($BZ275:$CC275,$BZ272:$CC272,CN8)+SUMIFS($AB329:$AT329,$AB326:$AT326,CN8)+SUMIFS($BZ329:$CC329,$BZ326:$CC326,CN8) | CO9: =SUMIFS($AB20:$AT20,$AB17:$AT17,CO8)+SUMIFS($BZ20:$CC20,$BZ17:$CC17,CO8)+SUMIFS($AB75:$AT75,$AB72:$AT72,CO8)+SUMIFS($BZ75:$CC75,$BZ72:$CC72,CO8)+SUMIFS($AB112:$AT112,$AB109:$AT109,CO8)+SUMIFS($BZ112:$CC112,$BZ109:$CC109,CO8)+SUMIFS($AB166:$AT166,$AB163:$AT163,CO8)+SUMIFS($BZ166:$CC166,$BZ163:$CC163,CO8)+SUMIFS($AB221:$AT221,$AB218:$AT218,CO8)+SUMIFS($BZ221:$CC221,$BZ218:$CC218,CO8)+SUMIFS($AB275:$AT275,$AB272:$AT272,CO8)+SUMIFS($BZ275:$CC275,$BZ272:$CC272,CO8)+SUMIFS($AB329:$AT329,$AB326:$AT326,CO8)+SUMIFS($BZ329:$CC329,$BZ326:$CC326,CO8) | CP9: =IFERROR(SUM(CH38,CH93,CH130,CH184,CH239,CH293,CH347)/CO9,0)
C10: REGENERANTS 1 - Premium | F10: Panachage 50 unités // Remise 15% pour BRI conso 10€ sur 4 produits : Sérum J/N, CDJR, CDJRI, sérum nuit RI (-10€ = prix plancher, à imprimer sur 1 SR sur le présentoir) | CM10: Institut | CN10: =SUMIFS($AV20:$BX20,$AV17:$BX17,CN8)+SUMIFS($AV75:$BX75,$AV72:$BX72,CN8)+SUMIFS($AV112:$BX112,$AV109:$BX109,CN8)+SUMIFS($AV166:$BX166,$AV163:$BX163,CN8)+SUMIFS($AV221:$BX221,$AV218:$BX218,CN8)+SUMIFS($AV275:$BX275,$AV272:$BX272,CN8)+SUMIFS($AV329:$BX329,$AV326:$BX326,CN8) | CO10: =SUMIFS($AV20:$BX20,$AV17:$BX17,CO8)+SUMIFS($AV75:$BX75,$AV72:$BX72,CO8)+SUMIFS($AV112:$BX112,$AV109:$BX109,CO8)+SUMIFS($AV166:$BX166,$AV163:$BX163,CO8)+SUMIFS($AV221:$BX221,$AV218:$BX218,CO8)+SUMIFS($AV275:$BX275,$AV272:$BX272,CO8)+SUMIFS($AV329:$BX329,$AV326:$BX326,CO8) | CP10: =IFERROR(SUM(CH44,CH99,CH136,CH190,CH245,CH299,CH353)/CO10,0)
AB12: 0.5 | AG12: 0.2 | AV12: 0.19 | BA12: 0.1
AB13: Tarif Retail | AV13: Tarif Institut | BZ13: Autres | CF13: Tous réseaux
P15: Additionnelle | AB15: Ambassadeur | AG15: Compagnon | AL15: Challenger | AQ15: Partenaire | AV15: Rose | BA15: Prunelier | BF15: Anthylide | BK15: Calendula | BP15: Bourrache | BU15: Herbacée | BZ15: Autres | CF15: Total
H17: Pdt dans offre | J17: PA x Unit. | K17: Coûts Achats | M17: Tarif Rev. x Unit. | N17: Tarif Rev. | P17: Remise Offres x Prod. | R17: Tarif Rev. Remisé | T17: PPC Unitaire Indicatif | V17: PPC Unitaire Remisé | X17: Montant BRI | Z17: PPC global Indicatif | AB17: Nbrs Offres planifiées | AC17: Remise Statut | AD17: CA | AE17: Marges | AG17: Nbrs Offres planifiées | AH17: Remise Statut | AI17: CA | AJ17: Marges | AL17: Nbrs Offres planifiées | AM17: Remise Statut | AN17: CA | AO17: Marges | AQ17: Nbrs Offres planifiées | AR17: Remise Statut | AS17: CA | AT17: Marges | AV17: Nbrs Offres planifiées | AW17: Remise Statut | AX17: CA | AY17: Marges | BA17: Nbrs Offres planifiées | BB17: Remise Statut | BC17: CA | BD17: Marges | BF17: Nbrs Offres planifiées | BG17: Remise Statut | BH17: CA | BI17: Marges | BK17: Nbrs Offres planifiées | BL17: Remise Statut | BM17: CA | BN17: Marges | BP17: Nbrs Offres planifiées | BQ17: Remise Statut | BR17: CA | BS17: Marges | BU17: Nbrs Offres planifiées | BV17: Remise Statut | BW17: CA | BX17: Marges | BZ17: Nbrs Offres planifiées | CA17: Remise Statut | CB17: CA | CC17: Marges | CF17: Nbrs Offres planifiées | CG17: CA | CH17: Marges | CN17: Marketing | CT17: Commerce | CW17: Diététiques | CX17: Instituts | CY17: Pharmacies | DB17: Grands Magasins | DE17: Pures Players | DP17: Autres | DQ17: Total | DR17: Dont total GC | DS17: Proj CA eshop | DT17: Proj CA GC | DU17: Total coûts | DX17: BESOIN TOTAL POUR COMMANDE ALLEMAGNE | EA17: MAJ le
C18: Code article | D18: Libellé article | E18: Code à barres (EAN) | F18: Typ. Prod | H18: '# | J18: '€ | K18: '€ | M18: '€ | N18: '€ | P18: '€ | R18: '€ | T18: '€ | V18: '€ | X18: '€ | Z18: '€ | AB18: '# | AC18: '€ | AD18: '€ | AE18: '€ | AG18: '# | AH18: '€ | AI18: '€ | AJ18: '€ | AL18: '# | AM18: '€ | AN18: '€ | AO18: '€ | AQ18: '# | AR18: '€ | AS18: '€ | AT18: '€ | AV18: '# | AW18: '€ | AX18: '€ | AY18: '€ | BA18: '# | BB18: '€ | BC18: '€ | BD18: '€ | BF18: '# | BG18: '€ | BH18: '€ | BI18: '€ | BK18: '# | BL18: '€ | BM18: '€ | BN18: '€ | BP18: '# | BQ18: '€ | BR18: '€ | BS18: '€ | BU18: '# | BV18: '€ | BW18: '€ | BX18: '€ | BZ18: '# | CA18: '€ | CB18: '€ | CC18: '€ | CF18: '# | CG18: '€ | CH18: '€ | CJ18: =ROUNDUP(CF20*40%,-1)
R19: <
B20: =C10 | C20: Synthèse | H20: =IFERROR(SUMIFS(H22:H62,F22:F62,"Produit Vente"),"Non trouvé") | J20: =IFERROR($K20/$H20,"Non Trouvé") | K20: =IFERROR(SUM(K22:K62),"Non Trouvé") | M20: =IFERROR($N20/$H20,"Non Trouvé") | N20: =IFERROR(SUM(N22:N62),"Non Trouvé") | P20: =IFERROR(-(R20-N20)/N20,"Non Trouvé") | R20: =IFERROR(SUM(R22:R62),"Non Trouvé") | T20: =IFERROR(SUM(T22:T62),"Non Trouvé") | V20: =IFERROR(SUM(V22:V62),"Non Trouvé") | X20: =IFERROR(SUM(X22:X62),"Non Trouvé") | Z20: =IFERROR(SUM(Z22:Z62),"Non Trouvé") | AB20: =ROUND($AB$9*AB12,0) | AC20: =IFERROR(VLOOKUP(AB15,'[1]Paramètres Généraux'!$O:$P,2,FALSE),"Non Trouvé") | AD20: =IFERROR(SUM(AD22:AD62),"Non Trouvé") | AE20: =IFERROR((AD20-$K20*AB20)/AD20,"Non Trouvé") | AG20: =ROUND($AB$9*AG12,0) | AH20: =IFERROR(VLOOKUP(AG15,'[1]Paramètres Généraux'!$O:$P,2,FALSE),"Non Trouvé") | AI20: =IFERROR(SUM(AI22:AI62),"Non Trouvé") | AJ20: =IFERROR((AI20-$K20*AG20)/AI20,"Non Trouvé") | AL20: =ROUND($AB$9*AL12,0) | AM20: =IFERROR(VLOOKUP(AL15,'[1]Paramètres Généraux'!$O:$P,2,FALSE),"Non Trouvé") | AN20: =IFERROR(SUM(AN22:AN62),"Non Trouvé") | AO20: =IFERROR((AN20-$K20*AL20)/AN20,"Non Trouvé") | AQ20: =ROUND($AB$9*AQ12,0) | AR20: =IFERROR(VLOOKUP(AQ15,'[1]Paramètres Généraux'!$O:$P,2,FALSE),"Non Trouvé") | AS20: =IFERROR(SUM(AS22:AS62),"Non Trouvé") | AT20: =IFERROR((AS20-$K20*AQ20)/AS20,"Non Trouvé") | AV20: =ROUND($AB$9*AV12,0) | AW20: =IFERROR(VLOOKUP(AV15,'[1]Paramètres Généraux'!$O:$P,2,FALSE),"Non Trouvé") | AX20: =IFERROR(SUM(AX22:AX62),"Non Trouvé") | AY20: =IFERROR((AX20-$K20*AV20)/AX20,"Non Trouvé") | BA20: =ROUND($AB$9*BA12,0) | BB20: =IFERROR(VLOOKUP(BA15,'[1]Paramètres Généraux'!$O:$P,2,FALSE),"Non Trouvé") | BC20: =IFERROR(SUM(BC22:BC62),"Non Trouvé") | BD20: =IFERROR((BC20-$K20*BA20)/BC20,"Non Trouvé") | BF20: =ROUND($AB$9*BF12,0) | BG20: =IFERROR(VLOOKUP(BF15,'[1]Paramètres Généraux'!$O:$P,2,FALSE),"Non Trouvé") | BH20: =IFERROR(SUM(BH22:BH62),"Non Trouvé") | BI20: =IFERROR((BH20-$K20*BF20)/BH20,"Non Trouvé") | BK20: =ROUND($AB$9*BK12,0) | BL20: =IFERROR(VLOOKUP(BK15,'[1]Paramètres Généraux'!$O:$P,2,FALSE),"Non Trouvé") | BM20: =IFERROR(SUM(BM22:BM62),"Non Trouvé") | BN20: =IFERROR((BM20-$K20*BK20)/BM20,"Non Trouvé") | BP20: =ROUND($AB$9*BP12,0) | BQ20: =IFERROR(VLOOKUP(BP15,'[1]Paramètres Généraux'!$O:$P,2,FALSE),"Non Trouvé") | BR20: =IFERROR(SUM(BR22:BR62),"Non Trouvé") | BS20: =IFERROR((BR20-$K20*BP20)/BR20,"Non Trouvé") | BU20: =ROUND($AB$9*BU12,0) | BV20: =IFERROR(VLOOKUP(BU15,'[1]Paramètres Généraux'!$O:$P,2,FALSE),"Non Trouvé") | BW20: =IFERROR(SUM(BW22:BW62),"Non Trouvé") | BX20: =IFERROR((BW20-$K20*BU20)/BW20,"Non Trouvé") | BZ20: =ROUND($AB$9*BZ12,0) | CA20: =IFERROR(VLOOKUP(BZ15,'[1]Paramètres Généraux'!$O:$P,2,FALSE),"Non Trouvé") | CB20: =IFERROR(SUM(CB22:CB62),"Non Trouvé") | CC20: =IFERROR((CB20-$K20*BZ20)/CB20,"Non Trouvé") | CF20: =SUMIFS($AB20:$CC20,$AB17:$CC17,CF17) | CG20: =SUMIFS($AB20:$CC20,$AB17:$CC17,CG17) | CH20: =IFERROR((CG20-$K20*CF20)/CG20,"Non Trouvé") | CJ20: =ROUNDUP(CF20*70%,-1) | CN20: Réassort | CO20: Eshop | CP20: Opé Marketing / Communication | CQ20: Devis | CR20: Formation | CS20: Maison DRH | CT20: Dotation Commerciaux | CU20: Animation | CV20: Cadeau Acheteur GC | CW20: Biocoop | CX20: Mlle Bio | CY20: Pharm'O Naturel | CZ20: Anton & Willem | DA20: Elsie Santé | DB20: Printemps & Soprintours | DC20: Samaritaine | DD20: Galeries Lafayette | DE20: Place des Tendances | DF20: Nocibé | DG20: Monoprix | DH20: Nuoo | DI20: Jolimoi | DJ20: La Belle Vie | DK20: Easypara | DL20: New Pharma | DM20: My Origins | DN20: Le Monde du Bio | DO20: Onatera | DP20: Boutique Nature | DX20: CODE ARTICLE | DY20: LIBELLE ARTICLE | DZ20: BESOIN | EA20: COMMANDE VALIDÉE
B22: 1 | C22: 1020202 | D22: =IFERROR(IF($C22="","",VLOOKUP($C22,'[1]Paramètres Articles'!$B:$G,2,FALSE)),"Non Trouvé") | E22: =IFERROR(IF($C22="","",_xlfn.XLOOKUP(REGENERANTS!$C22,'[1]New Base PA'!$F:$F,'[1]New Base PA'!$D:$D,"Not Found",0)),"Non Trouvé") | F22: Produit Vente | H22: 7 | J22: =IFERROR(IF($C22="","",VLOOKUP($C22,'[1]New Base PA'!$F:$J,5,FALSE)),"Non Trouvé") | K22: =IFERROR(IF($C22="","",$J22*$H22),"Non Trouvé") | M22: =IFERROR(IF(AND($F22="Produit Vente",H22>0),VLOOKUP($C22,'[1]Paramètres Articles'!$B:$G,6,FALSE),0),"Non Trouvé") | N22: =IFERROR(IF($C22="","",$M22*$H22),"Non Trouvé") | P22: 0.15 | R22: =IFERROR(IF($C22="","",$N22*(1-$P22)),"Non Trouvé") | T22: =IFERROR(IF($C22="","",VLOOKUP($C22,'[1]Paramètres Articles'!$B:$H,7,FALSE)),"Non Trouvé") | V22: =IFERROR(IF($C22="","",IF($P22="","",$T22*(1-$P22))),"Non Trouvé") | X22: =IFERROR(T22-V22,"") | Z22: =IFERROR(IF(OR(T22=0,T22=""),0,T22*H22),"Non Trouvé") | AB22: =AB20 | AC22: =AC20 | AD22: =IFERROR(IF($C22="","",IF($P$15="Cascade",$R22*(1-AC22)*AB22,IF($P$15="Additionnelle",($N22-($N22*($P22+AC22)))*AB22))),"Non Trouvé") | AG22: =AG20 | AH22: =AH20 | AI22: =IFERROR(IF($C22="","",IF($P$15="Cascade",$R22*(1-AH22)*AG22,IF($P$15="Additionnelle",($N22-($N22*($P22+AH22)))*AG22))),"Non Trouvé") | AL22: =AL20 | AM22: =AM20 | AN22: =IFERROR(IF($C22="","",IF($P$15="Cascade",$R22*(1-AM22)*AL22,IF($P$15="Additionnelle",($N22-($N22*($P22+AM22)))*AL22))),"Non Trouvé") | AQ22: =AQ20 | AR22: =AR20 | AS22: =IFERROR(IF($C22="","",IF($P$15="Cascade",$R22*(1-AR22)*AQ22,IF($P$15="Additionnelle",($N22-($N22*($P22+AR22)))*AQ22))),"Non Trouvé") | AV22: =AV20 | AW22: =AW20 | AX22: =IFERROR(IF($C22="","",IF($P$15="Cascade",$R22*(1-AW22)*AV22,IF($P$15="Additionnelle",($N22-($N22*($P22+AW22)))*AV22))),"Non Trouvé") | BA22: =BA20 | BB22: =BB20 | BC22: =IFERROR(IF($C22="","",IF($P$15="Cascade",$R22*(1-BB22)*BA22,IF($P$15="Additionnelle",($N22-($N22*($P22+BB22)))*BA22))),"Non Trouvé") | BF22: =BF20 | BG22: =BG20 | BH22: =IFERROR(IF($C22="","",IF($P$15="Cascade",$R22*(1-BG22)*BF22,IF($P$15="Additionnelle",($N22-($N22*($P22+BG22)))*BF22))),"Non Trouvé") | BK22: =BK20 | BL22: =BL20 | BM22: =IFERROR(IF($C22="","",IF($P$15="Cascade",$R22*(1-BL22)*BK22,IF($P$15="Additionnelle",($N22-($N22*($P22+BL22)))*BK22))),"Non Trouvé") | BP22: =BP20 | BQ22: =BQ20 | BR22: =IFERROR(IF($C22="","",IF($P$15="Cascade",$R22*(1-BQ22)*BP22,IF($P$15="Additionnelle",($N22-($N22*($P22+BQ22)))*BP22))),"Non Trouvé") | BU22: =BU20 | BV22: =BV20 | BW22: =IFERROR(IF($C22="","",IF($P$15="Cascade",$R22*(1-BV22)*BU22,IF($P$15="Additionnelle",($N22-($N22*($P22+BV22)))*BU22))),"Non Trouvé") | BZ22: =BZ20 | CA22: =CA20 | CB22: =IFERROR(IF($C22="","",IF($P$15="Cascade",$R22*(1-CA22)*BZ22,IF($P$15="Additionnelle",($N22-($N22*($P22+CA22)))*BZ22))),"Non Trouvé") | CK22: =IFERROR(IF(F22='[1]Paramètres Généraux'!$K$12,ROUNDUP((REGENERANTS!H22*REGENERANTS!$CF$20)*'[1]Paramètres Généraux'!$M$12,-1),IF(F22='[1]Paramètres Généraux'!$K$15,ROUNDUP((REGENERANTS!H22*REGENERANTS!$CF$20)*'[1]Paramètres Généraux'!$M$15,-1),REGENERANTS!H22*REGENERANTS!$CF$20)),"nd") | DQ22: =SUM(CN22:DP22) | DR22: =SUM(CV22:DP22) | DS22: =IFERROR((IF(AND($F22="Produit Vente",CO22>0),VLOOKUP($C22,'[1]Paramètres Articles'!$B:$H,7,FALSE)*$CO22)*(1-20%)),0) | DT22: =IFERROR((IF(AND($F22="Produit Vente",DR22>0),VLOOKUP($C22,'[1]Paramètres Articles'!$B:$H,6,FALSE)*$DR22)*(1-15%)),0) | DU22: =IFERROR(DQ22*J22,0) | DY22: =VLOOKUP(DX22,C:D,2,FALSE) | DZ22: =SUMIFS('[1]Moteur Produits'!$C:$C,'[1]Moteur Produits'!$B:$B,$DX22)
B23: =IF(C23="",0,COUNTIFS($B$22:B22,">"&0)+1) | C23: 1020310 | D23: =IFERROR(IF($C23="","",VLOOKUP($C23,'[1]Paramètres Articles'!$B:$G,2,FALSE)),"Non Trouvé") | E23: =IFERROR(IF($C23="","",_xlfn.XLOOKUP(REGENERANTS!$C23,'[1]New Base PA'!$F:$F,'[1]New Base PA'!$D:$D,"Not Found",0)),"Non Trouvé") | F23: Produit Vente | H23: 4 | J23: =IFERROR(IF($C23="","",VLOOKUP($C23,'[1]New Base PA'!$F:$J,5,FALSE)),"Non Trouvé") | K23: =IFERROR(IF($C23="","",$J23*$H23),"Non Trouvé") | M23: =IFERROR(IF(AND($F23="Produit Vente",H23>0),VLOOKUP($C23,'[1]Paramètres Articles'!$B:$G,6,FALSE),0),"Non Trouvé") | N23: =IFERROR(IF($C23="","",$M23*$H23),"Non Trouvé") | P23: 0.15 | R23: =IFERROR(IF($C23="","",$N23*(1-$P23)),"Non Trouvé") | T23: =IFERROR(IF($C23="","",VLOOKUP($C23,'[1]Paramètres Articles'!$B:$H,7,FALSE)),"Non Trouvé") | V23: =IFERROR(IF($C23="","",IF($P23="","",$T23*(1-$P23))),"Non Trouvé") | X23: =IFERROR(T23-V23,"") | Z23: =IFERROR(IF(OR(T23=0,T23=""),0,T23*H23),"Non Trouvé") | AB23: =AB22 | AC23: =AC22 | AD23: =IFERROR(IF($C23="","",IF($P$15="Cascade",$R23*(1-AC23)*AB23,IF($P$15="Additionnelle",($N23-($N23*($P23+AC23)))*AB23))),"Non Trouvé") | AG23: =AG22 | AH23: =AH22 | AI23: =IFERROR(IF($C23="","",IF($P$15="Cascade",$R23*(1-AH23)*AG23,IF($P$15="Additionnelle",($N23-($N23*($P23+AH23)))*AG23))),"Non Trouvé") | AL23: =AL22 | AM23: =AM22 | AN23: =IFERROR(IF($C23="","",IF($P$15="Cascade",$R23*(1-AM23)*AL23,IF($P$15="Additionnelle",($N23-($N23*($P23+AM23)))*AL23))),"Non Trouvé") | AQ23: =AQ22 | AR23: =AR22 | AS23: =IFERROR(IF($C23="","",IF($P$15="Cascade",$R23*(1-AR23)*AQ23,IF($P$15="Additionnelle",($N23-($N23*($P23+AR23)))*AQ23))),"Non Trouvé") | AV23: =AV22 | AW23: =AW22 | AX23: =IFERROR(IF($C23="","",IF($P$15="Cascade",$R23*(1-AW23)*AV23,IF($P$15="Additionnelle",($N23-($N23*($P23+AW23)))*AV23))),"Non Trouvé") | BA23: =BA22 | BB23: =BB22 | BC23: =IFERROR(IF($C23="","",IF($P$15="Cascade",$R23*(1-BB23)*BA23,IF($P$15="Additionnelle",($N23-($N23*($P23+BB23)))*BA23))),"Non Trouvé") | BF23: =BF22 | BG23: =BG22 | BH23: =IFERROR(IF($C23="","",IF($P$15="Cascade",$R23*(1-BG23)*BF23,IF($P$15="Additionnelle",($N23-($N23*($P23+BG23)))*BF23))),"Non Trouvé") | BK23: =BK22 | BL23: =BL22 | BM23: =IFERROR(IF($C23="","",IF($P$15="Cascade",$R23*(1-BL23)*BK23,IF($P$15="Additionnelle",($N23-($N23*($P23+BL23)))*BK23))),"Non Trouvé") | BP23: =BP22 | BQ23: =BQ22 | BR23: =IFERROR(IF($C23="","",IF($P$15="Cascade",$R23*(1-BQ23)*BP23,IF($P$15="Additionnelle",($N23-($N23*($P23+BQ23)))*BP23))),"Non Trouvé") | BU23: =BU22 | BV23: =BV22 | BW23: =IFERROR(IF($C23="","",IF($P$15="Cascade",$R23*(1-BV23)*BU23,IF($P$15="Additionnelle",($N23-($N23*($P23+BV23)))*BU23))),"Non Trouvé") | BZ23: =BZ22 | CA23: =CA22 | CB23: =IFERROR(IF($C23="","",IF($P$15="Cascade",$R23*(1-CA23)*BZ23,IF($P$15="Additionnelle",($N23-($N23*($P23+CA23)))*BZ23))),"Non Trouvé") | CG23: Prix Offre Moy. Remisé : | CH23: =CG20/CF20 | CK23: =IFERROR(IF(F23='[1]Paramètres Généraux'!$K$12,ROUNDUP((REGENERANTS!H23*REGENERANTS!$CF$20)*'[1]Paramètres Généraux'!$M$12,-1),IF(F23='[1]Paramètres Généraux'!$K$15,ROUNDUP((REGENERANTS!H23*REGENERANTS!$CF$20)*'[1]Paramètres Généraux'!$M$15,-1),REGENERANTS!H23*REGENERANTS!$CF$20)),"nd") | DQ23: =SUM(CN23:DP23) | DR23: =SUM(CV23:DP23) | DS23: =IFERROR((IF(AND($F23="Produit Vente",CO23>0),VLOOKUP($C23,'[1]Paramètres Articles'!$B:$H,7,FALSE)*$CO23)*(1-20%)),0) | DT23: =IFERROR((IF(AND($F23="Produit Vente",DR23>0),VLOOKUP($C23,'[1]Paramètres Articles'!$B:$H,6,FALSE)*$DR23)*(1-15%)),0) | DU23: =IFERROR(DQ23*J23,0) | DY23: =VLOOKUP(DX23,C:D,2,FALSE) | DZ23: =SUMIFS('[1]Moteur Produits'!$C:$C,'[1]Moteur Produits'!$B:$B,$DX23)
B24: =IF(C24="",0,COUNTIFS($B$22:B23,">"&0)+1) | C24: 1020401 | D24: =IFERROR(IF($C24="","",VLOOKUP($C24,'[1]Paramètres Articles'!$B:$G,2,FALSE)),"Non Trouvé") | E24: =IFERROR(IF($C24="","",_xlfn.XLOOKUP(REGENERANTS!$C24,'[1]New Base PA'!$F:$F,'[1]New Base PA'!$D:$D,"Not Found",0)),"Non Trouvé") | F24: Produit Vente | H24: 5 | J24: =IFERROR(IF($C24="","",VLOOKUP($C24,'[1]New Base PA'!$F:$J,5,FALSE)),"Non Trouvé") | K24: =IFERROR(IF($C24="","",$J24*$H24),"Non Trouvé") | M24: =IFERROR(IF(AND($F24="Produit Vente",H24>0),VLOOKUP($C24,'[1]Paramètres Articles'!$B:$G,6,FALSE),0),"Non Trouvé") | N24: =IFERROR(IF($C24="","",$M24*$H24),"Non Trouvé") | P24: 0.15 | R24: =IFERROR(IF($C24="","",$N24*(1-$P24)),"Non Trouvé") | T24: =IFERROR(IF($C24="","",VLOOKUP($C24,'[1]Paramètres Articles'!$B:$H,7,FALSE)),"Non Trouvé") | V24: =IFERROR(IF($C24="","",IF($P24="","",$T24*(1-$P24))),"Non Trouvé") | X24: =IFERROR(T24-V24,"") | Z24: =IFERROR(IF(OR(T24=0,T24=""),0,T24*H24),"Non Trouvé") | AB24: =AB23 | AC24: =AC23 | AD24: =IFERROR(IF($C24="","",IF($P$15="Cascade",$R24*(1-AC24)*AB24,IF($P$15="Additionnelle",($N24-($N24*($P24+AC24)))*AB24))),"Non Trouvé") | AG24: =AG23 | AH24: =AH23 | AI24: =IFERROR(IF($C24="","",IF($P$15="Cascade",$R24*(1-AH24)*AG24,IF($P$15="Additionnelle",($N24-($N24*($P24+AH24)))*AG24))),"Non Trouvé") | AL24: =AL23 | AM24: =AM23 | AN24: =IFERROR(IF($C24="","",IF($P$15="Cascade",$R24*(1-AM24)*AL24,IF($P$15="Additionnelle",($N24-($N24*($P24+AM24)))*AL24))),"Non Trouvé") | AQ24: =AQ23 | AR24: =AR23 | AS24: =IFERROR(IF($C24="","",IF($P$15="Cascade",$R24*(1-AR24)*AQ24,IF($P$15="Additionnelle",($N24-($N24*($P24+AR24)))*AQ24))),"Non Trouvé") | AV24: =AV23 | AW24: =AW23 | AX24: =IFERROR(IF($C24="","",IF($P$15="Cascade",$R24*(1-AW24)*AV24,IF($P$15="Additionnelle",($N24-($N24*($P24+AW24)))*AV24))),"Non Trouvé") | BA24: =BA23 | BB24: =BB23 | BC24: =IFERROR(IF($C24="","",IF($P$15="Cascade",$R24*(1-BB24)*BA24,IF($P$15="Additionnelle",($N24-($N24*($P24+BB24)))*BA24))),"Non Trouvé") | BF24: =BF23 | BG24: =BG23 | BH24: =IFERROR(IF($C24="","",IF($P$15="Cascade",$R24*(1-BG24)*BF24,IF($P$15="Additionnelle",($N24-($N24*($P24+BG24)))*BF24))),"Non Trouvé") | BK24: =BK23 | BL24: =BL23 | BM24: =IFERROR(IF($C24="","",IF($P$15="Cascade",$R24*(1-BL24)*BK24,IF($P$15="Additionnelle",($N24-($N24*($P24+BL24)))*BK24))),"Non Trouvé") | BP24: =BP23 | BQ24: =BQ23 | BR24: =IFERROR(IF($C24="","",IF($P$15="Cascade",$R24*(1-BQ24)*BP24,IF($P$15="Additionnelle",($N24-($N24*($P24+BQ24)))*BP24))),"Non Trouvé") | BU24: =BU23 | BV24: =BV23 | BW24: =IFERROR(IF($C24="","",IF($P$15="Cascade",$R24*(1-BV24)*BU24,IF($P$15="Additionnelle",($N24-($N24*($P24+BV24)))*BU24))),"Non Trouvé") | BZ24: =BZ23 | CA24: =CA23 | CB24: =IFERROR(IF($C24="","",IF($P$15="Cascade",$R24*(1-CA24)*BZ24,IF($P$15="Additionnelle",($N24-($N24*($P24+CA24)))*BZ24))),"Non Trouvé") | CG24: Poids Gratuités achats : | CH24: =SUM(CH26:CH29) | CK24: =IFERROR(IF(F24='[1]Paramètres Généraux'!$K$12,ROUNDUP((REGENERANTS!H24*REGENERANTS!$CF$20)*'[1]Paramètres Généraux'!$M$12,-1),IF(F24='[1]Paramètres Généraux'!$K$15,ROUNDUP((REGENERANTS!H24*REGENERANTS!$CF$20)*'[1]Paramètres Généraux'!$M$15,-1),REGENERANTS!H24*REGENERANTS!$CF$20)),"nd") | DQ24: =SUM(CN24:DP24) | DR24: =SUM(CV24:DP24) | DS24: =IFERROR((IF(AND($F24="Produit Vente",CO24>0),VLOOKUP($C24,'[1]Paramètres Articles'!$B:$H,7,FALSE)*$CO24)*(1-20%)),0) | DT24: =IFERROR((IF(AND($F24="Produit Vente",DR24>0),VLOOKUP($C24,'[1]Paramètres Articles'!$B:$H,6,FALSE)*$DR24)*(1-15%)),0) | DU24: =IFERROR(DQ24*J24,0) | DY24: =VLOOKUP(DX24,C:D,2,FALSE) | DZ24: =SUMIFS('[1]Moteur Produits'!$C:$C,'[1]Moteur Produits'!$B:$B,$DX24)
B25: =IF(C25="",0,COUNTIFS($B$22:B24,">"&0)+1) | C25: 1020302 | D25: =IFERROR(IF($C25="","",VLOOKUP($C25,'[1]Paramètres Articles'!$B:$G,2,FALSE)),"Non Trouvé") | E25: =IFERROR(IF($C25="","",_xlfn.XLOOKUP(REGENERANTS!$C25,'[1]New Base PA'!$F:$F,'[1]New Base PA'!$D:$D,"Not Found",0)),"Non Trouvé") | F25: Produit Vente | H25: 1 | J25: =IFERROR(IF($C25="","",VLOOKUP($C25,'[1]New Base PA'!$F:$J,5,FALSE)),"Non Trouvé") | K25: =IFERROR(IF($C25="","",$J25*$H25),"Non Trouvé") | M25: =IFERROR(IF(AND($F25="Produit Vente",H25>0),VLOOKUP($C25,'[1]Paramètres Articles'!$B:$G,6,FALSE),0),"Non Trouvé") | N25: =IFERROR(IF($C25="","",$M25*$H25),"Non Trouvé") | P25: 0.15 | R25: =IFERROR(IF($C25="","",$N25*(1-$P25)),"Non Trouvé") | T25: =IFERROR(IF($C25="","",VLOOKUP($C25,'[1]Paramètres Articles'!$B:$H,7,FALSE)),"Non Trouvé") | V25: =IFERROR(IF($C25="","",IF($P25="","",$T25*(1-$P25))),"Non Trouvé") | X25: =IFERROR(T25-V25,"") | Z25: =IFERROR(IF(OR(T25=0,T25=""),0,T25*H25),"Non Trouvé") | AB25: =AB24 | AC25: =AC24 | AD25: =IFERROR(IF($C25="","",IF($P$15="Cascade",$R25*(1-AC25)*AB25,IF($P$15="Additionnelle",($N25-($N25*($P25+AC25)))*AB25))),"Non Trouvé") | AG25: =AG24 | AH25: =AH24 | AI25: =IFERROR(IF($C25="","",IF($P$15="Cascade",$R25*(1-AH25)*AG25,IF($P$15="Additionnelle",($N25-($N25*($P25+AH25)))*AG25))),"Non Trouvé") | AL25: =AL24 | AM25: =AM24 | AN25: =IFERROR(IF($C25="","",IF($P$15="Cascade",$R25*(1-AM25)*AL25,IF($P$15="Additionnelle",($N25-($N25*($P25+AM25)))*AL25))),"Non Trouvé") | AQ25: =AQ24 | AR25: =AR24 | AS25: =IFERROR(IF($C25="","",IF($P$15="Cascade",$R25*(1-AR25)*AQ25,IF($P$15="Additionnelle",($N25-($N25*($P25+AR25)))*AQ25))),"Non Trouvé") | AV25: =AV24 | AW25: =AW24 | AX25: =IFERROR(IF($C25="","",IF($P$15="Cascade",$R25*(1-AW25)*AV25,IF($P$15="Additionnelle",($N25-($N25*($P25+AW25)))*AV25))),"Non Trouvé") | BA25: =BA24 | BB25: =BB24 | BC25: =IFERROR(IF($C25="","",IF($P$15="Cascade",$R25*(1-BB25)*BA25,IF($P$15="Additionnelle",($N25-($N25*($P25+BB25)))*BA25))),"Non Trouvé") | BF25: =BF24 | BG25: =BG24 | BH25: =IFERROR(IF($C25="","",IF($P$15="Cascade",$R25*(1-BG25)*BF25,IF($P$15="Additionnelle",($N25-($N25*($P25+BG25)))*BF25))),"Non Trouvé") | BK25: =BK24 | BL25: =BL24 | BM25: =IFERROR(IF($C25="","",IF($P$15="Cascade",$R25*(1-BL25)*BK25,IF($P$15="Additionnelle",($N25-($N25*($P25+BL25)))*BK25))),"Non Trouvé") | BP25: =BP24 | BQ25: =BQ24 | BR25: =IFERROR(IF($C25="","",IF($P$15="Cascade",$R25*(1-BQ25)*BP25,IF($P$15="Additionnelle",($N25-($N25*($P25+BQ25)))*BP25))),"Non Trouvé") | BU25: =BU24 | BV25: =BV24 | BW25: =IFERROR(IF($C25="","",IF($P$15="Cascade",$R25*(1-BV25)*BU25,IF($P$15="Additionnelle",($N25-($N25*($P25+BV25)))*BU25))),"Non Trouvé") | BZ25: =BZ24 | CA25: =CA24 | CB25: =IFERROR(IF($C25="","",IF($P$15="Cascade",$R25*(1-CA25)*BZ25,IF($P$15="Additionnelle",($N25-($N25*($P25+CA25)))*BZ25))),"Non Trouvé") | CK25: =IFERROR(IF(F25='[1]Paramètres Généraux'!$K$12,ROUNDUP((REGENERANTS!H25*REGENERANTS!$CF$20)*'[1]Paramètres Généraux'!$M$12,-1),IF(F25='[1]Paramètres Généraux'!$K$15,ROUNDUP((REGENERANTS!H25*REGENERANTS!$CF$20)*'[1]Paramètres Généraux'!$M$15,-1),REGENERANTS!H25*REGENERANTS!$CF$20)),"nd") | DQ25: =SUM(CN25:DP25) | DR25: =SUM(CV25:DP25) | DS25: =IFERROR((IF(AND($F25="Produit Vente",CO25>0),VLOOKUP($C25,'[1]Paramètres Articles'!$B:$H,7,FALSE)*$CO25)*(1-20%)),0) | DT25: =IFERROR((IF(AND($F25="Produit Vente",DR25>0),VLOOKUP($C25,'[1]Paramètres Articles'!$B:$H,6,FALSE)*$DR25)*(1-15%)),0) | DU25: =IFERROR(DQ25*J25,0) | DY25: =VLOOKUP(DX25,C:D,2,FALSE) | DZ25: =SUMIFS('[1]Moteur Produits'!$C:$C,'[1]Moteur Produits'!$B:$B,$DX25)
B26: =IF(C26="",0,COUNTIFS($B$22:B25,">"&0)+1) | C26: 1020721 | D26: =IFERROR(IF($C26="","",VLOOKUP($C26,'[1]Paramètres Articles'!$B:$G,2,FALSE)),"Non Trouvé") | E26: =IFERROR(IF($C26="","",_xlfn.XLOOKUP(REGENERANTS!$C26,'[1]New Base PA'!$F:$F,'[1]New Base PA'!$D:$D,"Not Found",0)),"Non Trouvé") | F26: Produit Vente | H26: 0 | J26: =IFERROR(IF($C26="","",VLOOKUP($C26,'[1]New Base PA'!$F:$J,5,FALSE)),"Non Trouvé") | K26: =IFERROR(IF($C26="","",$J26*$H26),"Non Trouvé") | M26: =IFERROR(IF(AND($F26="Produit Vente",H26>0),VLOOKUP($C26,'[1]Paramètres Articles'!$B:$G,6,FALSE),0),"Non Trouvé") | N26: =IFERROR(IF($C26="","",$M26*$H26),"Non Trouvé") | P26: 0.15 | R26: =IFERROR(IF($C26="","",$N26*(1-$P26)),"Non Trouvé") | T26: =IFERROR(IF($C26="","",VLOOKUP($C26,'[1]Paramètres Articles'!$B:$H,7,FALSE)),"Non Trouvé") | V26: =IFERROR(IF($C26="","",IF($P26="","",$T26*(1-$P26))),"Non Trouvé") | X26: =IFERROR(T26-V26,"") | Z26: =IFERROR(IF(OR(T26=0,T26=""),0,T26*H26),"Non Trouvé") | AB26: =AB25 | AC26: =AC25 | AD26: =IFERROR(IF($C26="","",IF($P$15="Cascade",$R26*(1-AC26)*AB26,IF($P$15="Additionnelle",($N26-($N26*($P26+AC26)))*AB26))),"Non Trouvé") | AG26: =AG25 | AH26: =AH25 | AI26: =IFERROR(IF($C26="","",IF($P$15="Cascade",$R26*(1-AH26)*AG26,IF($P$15="Additionnelle",($N26-($N26*($P26+AH26)))*AG26))),"Non Trouvé") | AL26: =AL25 | AM26: =AM25 | AN26: =IFERROR(IF($C26="","",IF($P$15="Cascade",$R26*(1-AM26)*AL26,IF($P$15="Additionnelle",($N26-($N26*($P26+AM26)))*AL26))),"Non Trouvé") | AQ26: =AQ25 | AR26: =AR25 | AS26: =IFERROR(IF($C26="","",IF($P$15="Cascade",$R26*(1-AR26)*AQ26,IF($P$15="Additionnelle",($N26-($N26*($P26+AR26)))*AQ26))),"Non Trouvé") | AV26: =AV25 | AW26: =AW25 | AX26: =IFERROR(IF($C26="","",IF($P$15="Cascade",$R26*(1-AW26)*AV26,IF($P$15="Additionnelle",($N26-($N26*($P26+AW26)))*AV26))),"Non Trouvé") | BA26: =BA25 | BB26: =BB25 | BC26: =IFERROR(IF($C26="","",IF($P$15="Cascade",$R26*(1-BB26)*BA26,IF($P$15="Additionnelle",($N26-($N26*($P26+BB26)))*BA26))),"Non Trouvé") | BF26: =BF25 | BG26: =BG25 | BH26: =IFERROR(IF($C26="","",IF($P$15="Cascade",$R26*(1-BG26)*BF26,IF($P$15="Additionnelle",($N26-($N26*($P26+BG26)))*BF26))),"Non Trouvé") | BK26: =BK25 | BL26: =BL25 | BM26: =IFERROR(IF($C26="","",IF($P$15="Cascade",$R26*(1-BL26)*BK26,IF($P$15="Additionnelle",($N26-($N26*($P26+BL26)))*BK26))),"Non Trouvé") | BP26: =BP25 | BQ26: =BQ25 | BR26: =IFERROR(IF($C26="","",IF($P$15="Cascade",$R26*(1-BQ26)*BP26,IF($P$15="Additionnelle",($N26-($N26*($P26+BQ26)))*BP26))),"Non Trouvé") | BU26: =BU25 | BV26: =BV25 | BW26: =IFERROR(IF($C26="","",IF($P$15="Cascade",$R26*(1-BV26)*BU26,IF($P$15="Additionnelle",($N26-($N26*($P26+BV26)))*BU26))),"Non Trouvé") | BZ26: =BZ25 | CA26: =CA25 | CB26: =IFERROR(IF($C26="","",IF($P$15="Cascade",$R26*(1-CA26)*BZ26,IF($P$15="Additionnelle",($N26-($N26*($P26+CA26)))*BZ26))),"Non Trouvé") | CG26: UG | CH26: =SUMIFS(K22:K62,F22:F62,CG26)/SUMIFS(K22:K62,F22:F62,"Produit Vente") | CK26: =IFERROR(IF(F26='[1]Paramètres Généraux'!$K$12,ROUNDUP((REGENERANTS!H26*REGENERANTS!$CF$20)*'[1]Paramètres Généraux'!$M$12,-1),IF(F26='[1]Paramètres Généraux'!$K$15,ROUNDUP((REGENERANTS!H26*REGENERANTS!$CF$20)*'[1]Paramètres Généraux'!$M$15,-1),REGENERANTS!H26*REGENERANTS!$CF$20)),"nd") | DQ26: =SUM(CN26:DP26) | DR26: =SUM(CV26:DP26) | DS26: =IFERROR((IF(AND($F26="Produit Vente",CO26>0),VLOOKUP($C26,'[1]Paramètres Articles'!$B:$H,7,FALSE)*$CO26)*(1-20%)),0) | DT26: =IFERROR((IF(AND($F26="Produit Vente",DR26>0),VLOOKUP($C26,'[1]Paramètres Articles'!$B:$H,6,FALSE)*$DR26)*(1-15%)),0) | DU26: =IFERROR(DQ26*J26,0) | DY26: =VLOOKUP(DX26,C:D,2,FALSE) | DZ26: =SUMIFS('[1]Moteur Produits'!$C:$C,'[1]Moteur Produits'!$B:$B,$DX26)
B27: =IF(C27="",0,COUNTIFS($B$22:B26,">"&0)+1) | C27: 1020107 | D27: =IFERROR(IF($C27="","",VLOOKUP($C27,'[1]Paramètres Articles'!$B:$G,2,FALSE)),"Non Trouvé") | E27: =IFERROR(IF($C27="","",_xlfn.XLOOKUP(REGENERANTS!$C27,'[1]New Base PA'!$F:$F,'[1]New Base PA'!$D:$D,"Not Found",0)),"Non Trouvé") | F27: Produit Vente | H27: 3 | J27: =IFERROR(IF($C27="","",VLOOKUP($C27,'[1]New Base PA'!$F:$J,5,FALSE)),"Non Trouvé") | K27: =IFERROR(IF($C27="","",$J27*$H27),"Non Trouvé") | M27: =IFERROR(IF(AND($F27="Produit Vente",H27>0),VLOOKUP($C27,'[1]Paramètres Articles'!$B:$G,6,FALSE),0),"Non Trouvé") | N27: =IFERROR(IF($C27="","",$M27*$H27),"Non Trouvé") | P27: 0.15 | R27: =IFERROR(IF($C27="","",$N27*(1-$P27)),"Non Trouvé") | T27: =IFERROR(IF($C27="","",VLOOKUP($C27,'[1]Paramètres Articles'!$B:$H,7,FALSE)),"Non Trouvé") | V27: =IFERROR(IF($C27="","",IF($P27="","",$T27*(1-$P27))),"Non Trouvé") | X27: =IFERROR(T27-V27,"") | Z27: =IFERROR(IF(OR(T27=0,T27=""),0,T27*H27),"Non Trouvé") | AB27: =AB26 | AC27: =AC26 | AD27: =IFERROR(IF($C27="","",IF($P$15="Cascade",$R27*(1-AC27)*AB27,IF($P$15="Additionnelle",($N27-($N27*($P27+AC27)))*AB27))),"Non Trouvé") | AG27: =AG26 | AH27: =AH26 | AI27: =IFERROR(IF($C27="","",IF($P$15="Cascade",$R27*(1-AH27)*AG27,IF($P$15="Additionnelle",($N27-($N27*($P27+AH27)))*AG27))),"Non Trouvé") | AL27: =AL26 | AM27: =AM26 | AN27: =IFERROR(IF($C27="","",IF($P$15="Cascade",$R27*(1-AM27)*AL27,IF($P$15="Additionnelle",($N27-($N27*($P27+AM27)))*AL27))),"Non Trouvé") | AQ27: =AQ26 | AR27: =AR26 | AS27: =IFERROR(IF($C27="","",IF($P$15="Cascade",$R27*(1-AR27)*AQ27,IF($P$15="Additionnelle",($N27-($N27*($P27+AR27)))*AQ27))),"Non Trouvé") | AV27: =AV26 | AW27: =AW26 | AX27: =IFERROR(IF($C27="","",IF($P$15="Cascade",$R27*(1-AW27)*AV27,IF($P$15="Additionnelle",($N27-($N27*($P27+AW27)))*AV27))),"Non Trouvé") | BA27: =BA26 | BB27: =BB26 | BC27: =IFERROR(IF($C27="","",IF($P$15="Cascade",$R27*(1-BB27)*BA27,IF($P$15="Additionnelle",($N27-($N27*($P27+BB27)))*BA27))),"Non Trouvé") | BF27: =BF26 | BG27: =BG26 | BH27: =IFERROR(IF($C27="","",IF($P$15="Cascade",$R27*(1-BG27)*BF27,IF($P$15="Additionnelle",($N27-($N27*($P27+BG27)))*BF27))),"Non Trouvé") | BK27: =BK26 | BL27: =BL26 | BM27: =IFERROR(IF($C27="","",IF($P$15="Cascade",$R27*(1-BL27)*BK27,IF($P$15="Additionnelle",($N27-($N27*($P27+BL27)))*BK27))),"Non Trouvé") | BP27: =BP26 | BQ27: =BQ26 | BR27: =IFERROR(IF($C27="","",IF($P$15="Cascade",$R27*(1-BQ27)*BP27,IF($P$15="Additionnelle",($N27-($N27*($P27+BQ27)))*BP27))),"Non Trouvé") | BU27: =BU26 | BV27: =BV26 | BW27: =IFERROR(IF($C27="","",IF($P$15="Cascade",$R27*(1-BV27)*BU27,IF($P$15="Additionnelle",($N27-($N27*($P27+BV27)))*BU27))),"Non Trouvé") | BZ27: =BZ26 | CA27: =CA26 | CB27: =IFERROR(IF($C27="","",IF($P$15="Cascade",$R27*(1-CA27)*BZ27,IF($P$15="Additionnelle",($N27-($N27*($P27+CA27)))*BZ27))),"Non Trouvé") | CG27: PLV | CH27: =(SUMIFS(K22:K62,F22:F62,"PLV (PDC ou autre)")+SUMIFS(K22:K62,F22:F62,"PLV (vitrine)"))/K20 | CK27: =IFERROR(IF(F27='[1]Paramètres Généraux'!$K$12,ROUNDUP((REGENERANTS!H27*REGENERANTS!$CF$20)*'[1]Paramètres Généraux'!$M$12,-1),IF(F27='[1]Paramètres Généraux'!$K$15,ROUNDUP((REGENERANTS!H27*REGENERANTS!$CF$20)*'[1]Paramètres Généraux'!$M$15,-1),REGENERANTS!H27*REGENERANTS!$CF$20)),"nd") | DQ27: =SUM(CN27:DP27) | DR27: =SUM(CV27:DP27) | DS27: =IFERROR((IF(AND($F27="Produit Vente",CO27>0),VLOOKUP($C27,'[1]Paramètres Articles'!$B:$H,7,FALSE)*$CO27)*(1-20%)),0) | DT27: =IFERROR((IF(AND($F27="Produit Vente",DR27>0),VLOOKUP($C27,'[1]Paramètres Articles'!$B:$H,6,FALSE)*$DR27)*(1-15%)),0) | DU27: =IFERROR(DQ27*J27,0)
B28: =IF(C28="",0,COUNTIFS($B$22:B27,">"&0)+1) | C28: 1020102 | D28: =IFERROR(IF($C28="","",VLOOKUP($C28,'[1]Paramètres Articles'!$B:$G,2,FALSE)),"Non Trouvé") | E28: =IFERROR(IF($C28="","",_xlfn.XLOOKUP(REGENERANTS!$C28,'[1]New Base PA'!$F:$F,'[1]New Base PA'!$D:$D,"Not Found",0)),"Non Trouvé") | F28: Produit Vente | H28: 3 | J28: =IFERROR(IF($C28="","",VLOOKUP($C28,'[1]New Base PA'!$F:$J,5,FALSE)),"Non Trouvé") | K28: =IFERROR(IF($C28="","",$J28*$H28),"Non Trouvé") | M28: =IFERROR(IF(AND($F28="Produit Vente",H28>0),VLOOKUP($C28,'[1]Paramètres Articles'!$B:$G,6,FALSE),0),"Non Trouvé") | N28: =IFERROR(IF($C28="","",$M28*$H28),"Non Trouvé") | P28: 0.15 | R28: =IFERROR(IF($C28="","",$N28*(1-$P28)),"Non Trouvé") | T28: =IFERROR(IF($C28="","",VLOOKUP($C28,'[1]Paramètres Articles'!$B:$H,7,FALSE)),"Non Trouvé") | V28: =IFERROR(IF($C28="","",IF($P28="","",$T28*(1-$P28))),"Non Trouvé") | X28: =IFERROR(T28-V28,"") | Z28: =IFERROR(IF(OR(T28=0,T28=""),0,T28*H28),"Non Trouvé") | AB28: =AB27 | AC28: =AC27 | AD28: =IFERROR(IF($C28="","",IF($P$15="Cascade",$R28*(1-AC28)*AB28,IF($P$15="Additionnelle",($N28-($N28*($P28+AC28)))*AB28))),"Non Trouvé") | AG28: =AG27 | AH28: =AH27 | AI28: =IFERROR(IF($C28="","",IF($P$15="Cascade",$R28*(1-AH28)*AG28,IF($P$15="Additionnelle",($N28-($N28*($P28+AH28)))*AG28))),"Non Trouvé") | AL28: =AL27 | AM28: =AM27 | AN28: =IFERROR(IF($C28="","",IF($P$15="Cascade",$R28*(1-AM28)*AL28,IF($P$15="Additionnelle",($N28-($N28*($P28+AM28)))*AL28))),"Non Trouvé") | AQ28: =AQ27 | AR28: =AR27 | AS28: =IFERROR(IF($C28="","",IF($P$15="Cascade",$R28*(1-AR28)*AQ28,IF($P$15="Additionnelle",($N28-($N28*($P28+AR28)))*AQ28))),"Non Trouvé") | AV28: =AV27 | AW28: =AW27 | AX28: =IFERROR(IF($C28="","",IF($P$15="Cascade",$R28*(1-AW28)*AV28,IF($P$15="Additionnelle",($N28-($N28*($P28+AW28)))*AV28))),"Non Trouvé") | BA28: =BA27 | BB28: =BB27 | BC28: =IFERROR(IF($C28="","",IF($P$15="Cascade",$R28*(1-BB28)*BA28,IF($P$15="Additionnelle",($N28-($N28*($P28+BB28)))*BA28))),"Non Trouvé") | BF28: =BF27 | BG28: =BG27 | BH28: =IFERROR(IF($C28="","",IF($P$15="Cascade",$R28*(1-BG28)*BF28,IF($P$15="Additionnelle",($N28-($N28*($P28+BG28)))*BF28))),"Non Trouvé") | BK28: =BK27 | BL28: =BL27 | BM28: =IFERROR(IF($C28="","",IF($P$15="Cascade",$R28*(1-BL28)*BK28,IF($P$15="Additionnelle",($N28-($N28*($P28+BL28)))*BK28))),"Non Trouvé") | BP28: =BP27 | BQ28: =BQ27 | BR28: =IFERROR(IF($C28="","",IF($P$15="Cascade",$R28*(1-BQ28)*BP28,IF($P$15="Additionnelle",($N28-($N28*($P28+BQ28)))*BP28))),"Non Trouvé") | BU28: =BU27 | BV28: =BV27 | BW28: =IFERROR(IF($C28="","",IF($P$15="Cascade",$R28*(1-BV28)*BU28,IF($P$15="Additionnelle",($N28-($N28*($P28+BV28)))*BU28))),"Non Trouvé") | BZ28: =BZ27 | CA28: =CA27 | CB28: =IFERROR(IF($C28="","",IF($P$15="Cascade",$R28*(1-CA28)*BZ28,IF($P$15="Additionnelle",($N28-($N28*($P28+CA28)))*BZ28))),"Non Trouvé") | CG28: Echantillon | CH28: =SUMIFS(K22:K62,F22:F62,CG28)/K20 | CK28: =IFERROR(IF(F28='[1]Paramètres Généraux'!$K$12,ROUNDUP((REGENERANTS!H28*REGENERANTS!$CF$20)*'[1]Paramètres Généraux'!$M$12,-1),IF(F28='[1]Paramètres Généraux'!$K$15,ROUNDUP((REGENERANTS!H28*REGENERANTS!$CF$20)*'[1]Paramètres Généraux'!$M$15,-1),REGENERANTS!H28*REGENERANTS!$CF$20)),"nd") | DQ28: =SUM(CN28:DP28) | DR28: =SUM(CV28:DP28) | DS28: =IFERROR((IF(AND($F28="Produit Vente",CO28>0),VLOOKUP($C28,'[1]Paramètres Articles'!$B:$H,7,FALSE)*$CO28)*(1-20%)),0) | DT28: =IFERROR((IF(AND($F28="Produit Vente",DR28>0),VLOOKUP($C28,'[1]Paramètres Articles'!$B:$H,6,FALSE)*$DR28)*(1-15%)),0) | DU28: =IFERROR(DQ28*J28,0)
B29: =IF(C29="",0,COUNTIFS($B$22:B28,">"&0)+1) | C29: 1020722 | D29: =IFERROR(IF($C29="","",VLOOKUP($C29,'[1]Paramètres Articles'!$B:$G,2,FALSE)),"Non Trouvé") | E29: =IFERROR(IF($C29="","",_xlfn.XLOOKUP(REGENERANTS!$C29,'[1]New Base PA'!$F:$F,'[1]New Base PA'!$D:$D,"Not Found",0)),"Non Trouvé") | F29: Produit Vente | H29: 0 | J29: =IFERROR(IF($C29="","",VLOOKUP($C29,'[1]New Base PA'!$F:$J,5,FALSE)),"Non Trouvé") | K29: =IFERROR(IF($C29="","",$J29*$H29),"Non Trouvé") | M29: =IFERROR(IF(AND($F29="Produit Vente",H29>0),VLOOKUP($C29,'[1]Paramètres Articles'!$B:$G,6,FALSE),0),"Non Trouvé") | N29: =IFERROR(IF($C29="","",$M29*$H29),"Non Trouvé") | P29: 0.15 | R29: =IFERROR(IF($C29="","",$N29*(1-$P29)),"Non Trouvé") | T29: =IFERROR(IF($C29="","",VLOOKUP($C29,'[1]Paramètres Articles'!$B:$H,7,FALSE)),"Non Trouvé") | V29: =IFERROR(IF($C29="","",IF($P29="","",$T29*(1-$P29))),"Non Trouvé") | X29: =IFERROR(T29-V29,"") | Z29: =IFERROR(IF(OR(T29=0,T29=""),0,T29*H29),"Non Trouvé") | AB29: =AB28 | AC29: =AC28 | AD29: =IFERROR(IF($C29="","",IF($P$15="Cascade",$R29*(1-AC29)*AB29,IF($P$15="Additionnelle",($N29-($N29*($P29+AC29)))*AB29))),"Non Trouvé") | AG29: =AG28 | AH29: =AH28 | AI29: =IFERROR(IF($C29="","",IF($P$15="Cascade",$R29*(1-AH29)*AG29,IF($P$15="Additionnelle",($N29-($N29*($P29+AH29)))*AG29))),"Non Trouvé") | AL29: =AL28 | AM29: =AM28 | AN29: =IFERROR(IF($C29="","",IF($P$15="Cascade",$R29*(1-AM29)*AL29,IF($P$15="Additionnelle",($N29-($N29*($P29+AM29)))*AL29))),"Non Trouvé") | AQ29: =AQ28 | AR29: =AR28 | AS29: =IFERROR(IF($C29="","",IF($P$15="Cascade",$R29*(1-AR29)*AQ29,IF($P$15="Additionnelle",($N29-($N29*($P29+AR29)))*AQ29))),"Non Trouvé") | AV29: =AV28 | AW29: =AW28 | AX29: =IFERROR(IF($C29="","",IF($P$15="Cascade",$R29*(1-AW29)*AV29,IF($P$15="Additionnelle",($N29-($N29*($P29+AW29)))*AV29))),"Non Trouvé") | BA29: =BA28 | BB29: =BB28 | BC29: =IFERROR(IF($C29="","",IF($P$15="Cascade",$R29*(1-BB29)*BA29,IF($P$15="Additionnelle",($N29-($N29*($P29+BB29)))*BA29))),"Non Trouvé") | BF29: =BF28 | BG29: =BG28 | BH29: =IFERROR(IF($C29="","",IF($P$15="Cascade",$R29*(1-BG29)*BF29,IF($P$15="Additionnelle",($N29-($N29*($P29+BG29)))*BF29))),"Non Trouvé") | BK29: =BK28 | BL29: =BL28 | BM29: =IFERROR(IF($C29="","",IF($P$15="Cascade",$R29*(1-BL29)*BK29,IF($P$15="Additionnelle",($N29-($N29*($P29+BL29)))*BK29))),"Non Trouvé") | BP29: =BP28 | BQ29: =BQ28 | BR29: =IFERROR(IF($C29="","",IF($P$15="Cascade",$R29*(1-BQ29)*BP29,IF($P$15="Additionnelle",($N29-($N29*($P29+BQ29)))*BP29))),"Non Trouvé") | BU29: =BU28 | BV29: =BV28 | BW29: =IFERROR(IF($C29="","",IF($P$15="Cascade",$R29*(1-BV29)*BU29,IF($P$15="Additionnelle",($N29-($N29*($P29+BV29)))*BU29))),"Non Trouvé") | BZ29: =BZ28 | CA29: =CA28 | CB29: =IFERROR(IF($C29="","",IF($P$15="Cascade",$R29*(1-CA29)*BZ29,IF($P$15="Additionnelle",($N29-($N29*($P29+CA29)))*BZ29))),"Non Trouvé") | CG29: Testeur | CH29: =SUMIFS(K22:K62,F22:F62,CG29)/K20 | CK29: =IFERROR(IF(F29='[1]Paramètres Généraux'!$K$12,ROUNDUP((REGENERANTS!H29*REGENERANTS!$CF$20)*'[1]Paramètres Généraux'!$M$12,-1),IF(F29='[1]Paramètres Généraux'!$K$15,ROUNDUP((REGENERANTS!H29*REGENERANTS!$CF$20)*'[1]Paramètres Généraux'!$M$15,-1),REGENERANTS!H29*REGENERANTS!$CF$20)),"nd") | DQ29: =SUM(CN29:DP29) | DR29: =SUM(CV29:DP29) | DS29: =IFERROR((IF(AND($F29="Produit Vente",CO29>0),VLOOKUP($C29,'[1]Paramètres Articles'!$B:$H,7,FALSE)*$CO29)*(1-20%)),0) | DT29: =IFERROR((IF(AND($F29="Produit Vente",DR29>0),VLOOKUP($C29,'[1]Paramètres Articles'!$B:$H,6,FALSE)*$DR29)*(1-15%)),0) | DU29: =IFERROR(DQ29*J29,0)
B30: =IF(C30="",0,COUNTIFS($B$22:B29,">"&0)+1) | C30: 1020719 | D30: =IFERROR(IF($C30="","",VLOOKUP($C30,'[1]Paramètres Articles'!$B:$G,2,FALSE)),"Non Trouvé") | E30: =IFERROR(IF($C30="","",_xlfn.XLOOKUP(REGENERANTS!$C30,'[1]New Base PA'!$F:$F,'[1]New Base PA'!$D:$D,"Not Found",0)),"Non Trouvé") | F30: Produit Vente | H30: 3 | J30: =IFERROR(IF($C30="","",VLOOKUP($C30,'[1]New Base PA'!$F:$J,5,FALSE)),"Non Trouvé") | K30: =IFERROR(IF($C30="","",$J30*$H30),"Non Trouvé") | M30: =IFERROR(IF(AND($F30="Produit Vente",H30>0),VLOOKUP($C30,'[1]Paramètres Articles'!$B:$G,6,FALSE),0),"Non Trouvé") | N30: =IFERROR(IF($C30="","",$M30*$H30),"Non Trouvé") | P30: 0.15 | R30: =IFERROR(IF($C30="","",$N30*(1-$P30)),"Non Trouvé") | T30: =IFERROR(IF($C30="","",VLOOKUP($C30,'[1]Paramètres Articles'!$B:$H,7,FALSE)),"Non Trouvé") | V30: =IFERROR(IF($C30="","",IF($P30="","",$T30*(1-$P30))),"Non Trouvé") | X30: =IFERROR(T30-V30,"") | Z30: =IFERROR(IF(OR(T30=0,T30=""),0,T30*H30),"Non Trouvé") | AB30: =AB29 | AC30: =AC29 | AD30: =IFERROR(IF($C30="","",IF($P$15="Cascade",$R30*(1-AC30)*AB30,IF($P$15="Additionnelle",($N30-($N30*($P30+AC30)))*AB30))),"Non Trouvé") | AG30: =AG29 | AH30: =AH29 | AI30: =IFERROR(IF($C30="","",IF($P$15="Cascade",$R30*(1-AH30)*AG30,IF($P$15="Additionnelle",($N30-($N30*($P30+AH30)))*AG30))),"Non Trouvé") | AL30: =AL29 | AM30: =AM29 | AN30: =IFERROR(IF($C30="","",IF($P$15="Cascade",$R30*(1-AM30)*AL30,IF($P$15="Additionnelle",($N30-($N30*($P30+AM30)))*AL30))),"Non Trouvé") | AQ30: =AQ29 | AR30: =AR29 | AS30: =IFERROR(IF($C30="","",IF($P$15="Cascade",$R30*(1-AR30)*AQ30,IF($P$15="Additionnelle",($N30-($N30*($P30+AR30)))*AQ30))),"Non Trouvé") | AV30: =AV29 | AW30: =AW29 | AX30: =IFERROR(IF($C30="","",IF($P$15="Cascade",$R30*(1-AW30)*AV30,IF($P$15="Additionnelle",($N30-($N30*($P30+AW30)))*AV30))),"Non Trouvé") | BA30: =BA29 | BB30: =BB29 | BC30: =IFERROR(IF($C30="","",IF($P$15="Cascade",$R30*(1-BB30)*BA30,IF($P$15="Additionnelle",($N30-($N30*($P30+BB30)))*BA30))),"Non Trouvé") | BF30: =BF29 | BG30: =BG29 | BH30: =IFERROR(IF($C30="","",IF($P$15="Cascade",$R30*(1-BG30)*BF30,IF($P$15="Additionnelle",($N30-($N30*($P30+BG30)))*BF30))),"Non Trouvé") | BK30: =BK29 | BL30: =BL29 | BM30: =IFERROR(IF($C30="","",IF($P$15="Cascade",$R30*(1-BL30)*BK30,IF($P$15="Additionnelle",($N30-($N30*($P30+BL30)))*BK30))),"Non Trouvé") | BP30: =BP29 | BQ30: =BQ29 | BR30: =IFERROR(IF($C30="","",IF($P$15="Cascade",$R30*(1-BQ30)*BP30,IF($P$15="Additionnelle",($N30-($N30*($P30+BQ30)))*BP30))),"Non Trouvé") | BU30: =BU29 | BV30: =BV29 | BW30: =IFERROR(IF($C30="","",IF($P$15="Cascade",$R30*(1-BV30)*BU30,IF($P$15="Additionnelle",($N30-($N30*($P30+BV30)))*BU30))),"Non Trouvé") | BZ30: =BZ29 | CA30: =CA29 | CB30: =IFERROR(IF($C30="","",IF($P$15="Cascade",$R30*(1-CA30)*BZ30,IF($P$15="Additionnelle",($N30-($N30*($P30+CA30)))*BZ30))),"Non Trouvé") | CK30: =IFERROR(IF(F30='[1]Paramètres Généraux'!$K$12,ROUNDUP((REGENERANTS!H30*REGENERANTS!$CF$20)*'[1]Paramètres Généraux'!$M$12,-1),IF(F30='[1]Paramètres Généraux'!$K$15,ROUNDUP((REGENERANTS!H30*REGENERANTS!$CF$20)*'[1]Paramètres Généraux'!$M$15,-1),REGENERANTS!H30*REGENERANTS!$CF$20)),"nd") | DQ30: =SUM(CN30:DP30) | DR30: =SUM(CV30:DP30) | DS30: =IFERROR((IF(AND($F30="Produit Vente",CO30>0),VLOOKUP($C30,'[1]Paramètres Articles'!$B:$H,7,FALSE)*$CO30)*(1-20%)),0) | DT30: =IFERROR((IF(AND($F30="Produit Vente",DR30>0),VLOOKUP($C30,'[1]Paramètres Articles'!$B:$H,6,FALSE)*$DR30)*(1-15%)),0) | DU30: =IFERROR(DQ30*J30,0)
B31: =IF(C31="",0,COUNTIFS($B$22:B30,">"&0)+1) | C31: 1020717 | D31: =IFERROR(IF($C31="","",VLOOKUP($C31,'[1]Paramètres Articles'!$B:$G,2,FALSE)),"Non Trouvé") | E31: =IFERROR(IF($C31="","",_xlfn.XLOOKUP(REGENERANTS!$C31,'[1]New Base PA'!$F:$F,'[1]New Base PA'!$D:$D,"Not Found",0)),"Non Trouvé") | F31: Produit Vente | H31: 3 | J31: =IFERROR(IF($C31="","",VLOOKUP($C31,'[1]New Base PA'!$F:$J,5,FALSE)),"Non Trouvé") | K31: =IFERROR(IF($C31="","",$J31*$H31),"Non Trouvé") | M31: =IFERROR(IF(AND($F31="Produit Vente",H31>0),VLOOKUP($C31,'[1]Paramètres Articles'!$B:$G,6,FALSE),0),"Non Trouvé") | N31: =IFERROR(IF($C31="","",$M31*$H31),"Non Trouvé") | P31: 0.15 | R31: =IFERROR(IF($C31="","",$N31*(1-$P31)),"Non Trouvé") | T31: =IFERROR(IF($C31="","",VLOOKUP($C31,'[1]Paramètres Articles'!$B:$H,7,FALSE)),"Non Trouvé") | V31: =IFERROR(IF($C31="","",IF($P31="","",$T31*(1-$P31))),"Non Trouvé") | X31: =IFERROR(T31-V31,"") | Z31: =IFERROR(IF(OR(T31=0,T31=""),0,T31*H31),"Non Trouvé") | AB31: =AB30 | AC31: =AC30 | AD31: =IFERROR(IF($C31="","",IF($P$15="Cascade",$R31*(1-AC31)*AB31,IF($P$15="Additionnelle",($N31-($N31*($P31+AC31)))*AB31))),"Non Trouvé") | AG31: =AG30 | AH31: =AH30 | AI31: =IFERROR(IF($C31="","",IF($P$15="Cascade",$R31*(1-AH31)*AG31,IF($P$15="Additionnelle",($N31-($N31*($P31+AH31)))*AG31))),"Non Trouvé") | AL31: =AL30 | AM31: =AM30 | AN31: =IFERROR(IF($C31="","",IF($P$15="Cascade",$R31*(1-AM31)*AL31,IF($P$15="Additionnelle",($N31-($N31*($P31+AM31)))*AL31))),"Non Trouvé") | AQ31: =AQ30 | AR31: =AR30 | AS31: =IFERROR(IF($C31="","",IF($P$15="Cascade",$R31*(1-AR31)*AQ31,IF($P$15="Additionnelle",($N31-($N31*($P31+AR31)))*AQ31))),"Non Trouvé") | AV31: =AV30 | AW31: =AW30 | AX31: =IFERROR(IF($C31="","",IF($P$15="Cascade",$R31*(1-AW31)*AV31,IF($P$15="Additionnelle",($N31-($N31*($P31+AW31)))*AV31))),"Non Trouvé") | BA31: =BA30 | BB31: =BB30 | BC31: =IFERROR(IF($C31="","",IF($P$15="Cascade",$R31*(1-BB31)*BA31,IF($P$15="Additionnelle",($N31-($N31*($P31+BB31)))*BA31))),"Non Trouvé") | BF31: =BF30 | BG31: =BG30 | BH31: =IFERROR(IF($C31="","",IF($P$15="Cascade",$R31*(1-BG31)*BF31,IF($P$15="Additionnelle",($N31-($N31*($P31+BG31)))*BF31))),"Non Trouvé") | BK31: =BK30 | BL31: =BL30 | BM31: =IFERROR(IF($C31="","",IF($P$15="Cascade",$R31*(1-BL31)*BK31,IF($P$15="Additionnelle",($N31-($N31*($P31+BL31)))*BK31))),"Non Trouvé") | BP31: =BP30 | BQ31: =BQ30 | BR31: =IFERROR(IF($C31="","",IF($P$15="Cascade",$R31*(1-BQ31)*BP31,IF($P$15="Additionnelle",($N31-($N31*($P31+BQ31)))*BP31))),"Non Trouvé") | BU31: =BU30 | BV31: =BV30 | BW31: =IFERROR(IF($C31="","",IF($P$15="Cascade",$R31*(1-BV31)*BU31,IF($P$15="Additionnelle",($N31-($N31*($P31+BV31)))*BU31))),"Non Trouvé") | BZ31: =BZ30 | CA31: =CA30 | CB31: =IFERROR(IF($C31="","",IF($P$15="Cascade",$R31*(1-CA31)*BZ31,IF($P$15="Additionnelle",($N31-($N31*($P31+CA31)))*BZ31))),"Non Trouvé") | CK31: =IFERROR(IF(F31='[1]Paramètres Généraux'!$K$12,ROUNDUP((REGENERANTS!H31*REGENERANTS!$CF$20)*'[1]Paramètres Généraux'!$M$12,-1),IF(F31='[1]Paramètres Généraux'!$K$15,ROUNDUP((REGENERANTS!H31*REGENERANTS!$CF$20)*'[1]Paramètres Généraux'!$M$15,-1),REGENERANTS!H31*REGENERANTS!$CF$20)),"nd") | DQ31: =SUM(CN31:DP31) | DR31: =SUM(CV31:DP31) | DS31: =IFERROR((IF(AND($F31="Produit Vente",CO31>0),VLOOKUP($C31,'[1]Paramètres Articles'!$B:$H,7,FALSE)*$CO31)*(1-20%)),0) | DT31: =IFERROR((IF(AND($F31="Produit Vente",DR31>0),VLOOKUP($C31,'[1]Paramètres Articles'!$B:$H,6,FALSE)*$DR31)*(1-15%)),0) | DU31: =IFERROR(DQ31*J31,0)
B32: =IF(C32="",0,COUNTIFS($B$22:B31,">"&0)+1) | C32: 1020718 | D32: =IFERROR(IF($C32="","",VLOOKUP($C32,'[1]Paramètres Articles'!$B:$G,2,FALSE)),"Non Trouvé") | E32: =IFERROR(IF($C32="","",_xlfn.XLOOKUP(REGENERANTS!$C32,'[1]New Base PA'!$F:$F,'[1]New Base PA'!$D:$D,"Not Found",0)),"Non Trouvé") | F32: Produit Vente | H32: 5 | J32: =IFERROR(IF($C32="","",VLOOKUP($C32,'[1]New Base PA'!$F:$J,5,FALSE)),"Non Trouvé") | K32: =IFERROR(IF($C32="","",$J32*$H32),"Non Trouvé") | M32: =IFERROR(IF(AND($F32="Produit Vente",H32>0),VLOOKUP($C32,'[1]Paramètres Articles'!$B:$G,6,FALSE),0),"Non Trouvé") | N32: =IFERROR(IF($C32="","",$M32*$H32),"Non Trouvé") | P32: 0.15 | R32: =IFERROR(IF($C32="","",$N32*(1-$P32)),"Non Trouvé") | T32: =IFERROR(IF($C32="","",VLOOKUP($C32,'[1]Paramètres Articles'!$B:$H,7,FALSE)),"Non Trouvé") | V32: =IFERROR(IF($C32="","",IF($P32="","",$T32*(1-$P32))),"Non Trouvé") | X32: =IFERROR(T32-V32,"") | Z32: =IFERROR(IF(OR(T32=0,T32=""),0,T32*H32),"Non Trouvé") | AB32: =AB31 | AC32: =AC31 | AD32: =IFERROR(IF($C32="","",IF($P$15="Cascade",$R32*(1-AC32)*AB32,IF($P$15="Additionnelle",($N32-($N32*($P32+AC32)))*AB32))),"Non Trouvé") | AG32: =AG31 | AH32: =AH31 | AI32: =IFERROR(IF($C32="","",IF($P$15="Cascade",$R32*(1-AH32)*AG32,IF($P$15="Additionnelle",($N32-($N32*($P32+AH32)))*AG32))),"Non Trouvé") | AL32: =AL31 | AM32: =AM31 | AN32: =IFERROR(IF($C32="","",IF($P$15="Cascade",$R32*(1-AM32)*AL32,IF($P$15="Additionnelle",($N32-($N32*($P32+AM32)))*AL32))),"Non Trouvé") | AQ32: =AQ31 | AR32: =AR31 | AS32: =IFERROR(IF($C32="","",IF($P$15="Cascade",$R32*(1-AR32)*AQ32,IF($P$15="Additionnelle",($N32-($N32*($P32+AR32)))*AQ32))),"Non Trouvé") | AV32: =AV31 | AW32: =AW31 | AX32: =IFERROR(IF($C32="","",IF($P$15="Cascade",$R32*(1-AW32)*AV32,IF($P$15="Additionnelle",($N32-($N32*($P32+AW32)))*AV32))),"Non Trouvé") | BA32: =BA31 | BB32: =BB31 | BC32: =IFERROR(IF($C32="","",IF($P$15="Cascade",$R32*(1-BB32)*BA32,IF($P$15="Additionnelle",($N32-($N32*($P32+BB32)))*BA32))),"Non Trouvé") | BF32: =BF31 | BG32: =BG31 | BH32: =IFERROR(IF($C32="","",IF($P$15="Cascade",$R32*(1-BG32)*BF32,IF($P$15="Additionnelle",($N32-($N32*($P32+BG32)))*BF32))),"Non Trouvé") | BK32: =BK31 | BL32: =BL31 | BM32: =IFERROR(IF($C32="","",IF($P$15="Cascade",$R32*(1-BL32)*BK32,IF($P$15="Additionnelle",($N32-($N32*($P32+BL32)))*BK32))),"Non Trouvé") | BP32: =BP31 | BQ32: =BQ31 | BR32: =IFERROR(IF($C32="","",IF($P$15="Cascade",$R32*(1-BQ32)*BP32,IF($P$15="Additionnelle",($N32-($N32*($P32+BQ32)))*BP32))),"Non Trouvé") | BU32: =BU31 | BV32: =BV31 | BW32: =IFERROR(IF($C32="","",IF($P$15="Cascade",$R32*(1-BV32)*BU32,IF($P$15="Additionnelle",($N32-($N32*($P32+BV32)))*BU32))),"Non Trouvé") | BZ32: =BZ31 | CA32: =CA31 | CB32: =IFERROR(IF($C32="","",IF($P$15="Cascade",$R32*(1-CA32)*BZ32,IF($P$15="Additionnelle",($N32-($N32*($P32+CA32)))*BZ32))),"Non Trouvé") | CK32: =IFERROR(IF(F32='[1]Paramètres Généraux'!$K$12,ROUNDUP((REGENERANTS!H32*REGENERANTS!$CF$20)*'[1]Paramètres Généraux'!$M$12,-1),IF(F32='[1]Paramètres Généraux'!$K$15,ROUNDUP((REGENERANTS!H32*REGENERANTS!$CF$20)*'[1]Paramètres Généraux'!$M$15,-1),REGENERANTS!H32*REGENERANTS!$CF$20)),"nd") | DQ32: =SUM(CN32:DP32) | DR32: =SUM(CV32:DP32) | DS32: =IFERROR((IF(AND($F32="Produit Vente",CO32>0),VLOOKUP($C32,'[1]Paramètres Articles'!$B:$H,7,FALSE)*$CO32)*(1-20%)),0) | DT32: =IFERROR((IF(AND($F32="Produit Vente",DR32>0),VLOOKUP($C32,'[1]Paramètres Articles'!$B:$H,6,FALSE)*$DR32)*(1-15%)),0) | DU32: =IFERROR(DQ32*J32,0)
B33: =IF(C33="",0,COUNTIFS($B$22:B32,">"&0)+1) | C33: 1020301 | D33: =IFERROR(IF($C33="","",VLOOKUP($C33,'[1]Paramètres Articles'!$B:$G,2,FALSE)),"Non Trouvé") | E33: =IFERROR(IF($C33="","",_xlfn.XLOOKUP(REGENERANTS!$C33,'[1]New Base PA'!$F:$F,'[1]New Base PA'!$D:$D,"Not Found",0)),"Non Trouvé") | F33: Produit Vente | H33: 8 | J33: =IFERROR(IF($C33="","",VLOOKUP($C33,'[1]New Base PA'!$F:$J,5,FALSE)),"Non Trouvé") | K33: =IFERROR(IF($C33="","",$J33*$H33),"Non Trouvé") | M33: =IFERROR(IF(AND($F33="Produit Vente",H33>0),VLOOKUP($C33,'[1]Paramètres Articles'!$B:$G,6,FALSE),0),"Non Trouvé") | N33: =IFERROR(IF($C33="","",$M33*$H33),"Non Trouvé") | P33: 0.15 | R33: =IFERROR(IF($C33="","",$N33*(1-$P33)),"Non Trouvé") | T33: =IFERROR(IF($C33="","",VLOOKUP($C33,'[1]Paramètres Articles'!$B:$H,7,FALSE)),"Non Trouvé") | V33: =IFERROR(IF($C33="","",IF($P33="","",$T33*(1-$P33))),"Non Trouvé") | X33: =IFERROR(T33-V33,"") | Z33: =IFERROR(IF(OR(T33=0,T33=""),0,T33*H33),"Non Trouvé") | AB33: =AB32 | AC33: =AC32 | AD33: =IFERROR(IF($C33="","",IF($P$15="Cascade",$R33*(1-AC33)*AB33,IF($P$15="Additionnelle",($N33-($N33*($P33+AC33)))*AB33))),"Non Trouvé") | AG33: =AG32 | AH33: =AH32 | AI33: =IFERROR(IF($C33="","",IF($P$15="Cascade",$R33*(1-AH33)*AG33,IF($P$15="Additionnelle",($N33-($N33*($P33+AH33)))*AG33))),"Non Trouvé") | AL33: =AL32 | AM33: =AM32 | AN33: =IFERROR(IF($C33="","",IF($P$15="Cascade",$R33*(1-AM33)*AL33,IF($P$15="Additionnelle",($N33-($N33*($P33+AM33)))*AL33))),"Non Trouvé") | AQ33: =AQ32 | AR33: =AR32 | AS33: =IFERROR(IF($C33="","",IF($P$15="Cascade",$R33*(1-AR33)*AQ33,IF($P$15="Additionnelle",($N33-($N33*($P33+AR33)))*AQ33))),"Non Trouvé") | AV33: =AV32 | AW33: =AW32 | AX33: =IFERROR(IF($C33="","",IF($P$15="Cascade",$R33*(1-AW33)*AV33,IF($P$15="Additionnelle",($N33-($N33*($P33+AW33)))*AV33))),"Non Trouvé") | BA33: =BA32 | BB33: =BB32 | BC33: =IFERROR(IF($C33="","",IF($P$15="Cascade",$R33*(1-BB33)*BA33,IF($P$15="Additionnelle",($N33-($N33*($P33+BB33)))*BA33))),"Non Trouvé") | BF33: =BF32 | BG33: =BG32 | BH33: =IFERROR(IF($C33="","",IF($P$15="Cascade",$R33*(1-BG33)*BF33,IF($P$15="Additionnelle",($N33-($N33*($P33+BG33)))*BF33))),"Non Trouvé") | BK33: =BK32 | BL33: =BL32 | BM33: =IFERROR(IF($C33="","",IF($P$15="Cascade",$R33*(1-BL33)*BK33,IF($P$15="Additionnelle",($N33-($N33*($P33+BL33)))*BK33))),"Non Trouvé") | BP33: =BP32 | BQ33: =BQ32 | BR33: =IFERROR(IF($C33="","",IF($P$15="Cascade",$R33*(1-BQ33)*BP33,IF($P$15="Additionnelle",($N33-($N33*($P33+BQ33)))*BP33))),"Non Trouvé") | BU33: =BU32 | BV33: =BV32 | BW33: =IFERROR(IF($C33="","",IF($P$15="Cascade",$R33*(1-BV33)*BU33,IF($P$15="Additionnelle",($N33-($N33*($P33+BV33)))*BU33))),"Non Trouvé") | BZ33: =BZ32 | CA33: =CA32 | CB33: =IFERROR(IF($C33="","",IF($P$15="Cascade",$R33*(1-CA33)*BZ33,IF($P$15="Additionnelle",($N33-($N33*($P33+CA33)))*BZ33))),"Non Trouvé") | CK33: =IFERROR(IF(F33='[1]Paramètres Généraux'!$K$12,ROUNDUP((REGENERANTS!H33*REGENERANTS!$CF$20)*'[1]Paramètres Généraux'!$M$12,-1),IF(F33='[1]Paramètres Généraux'!$K$15,ROUNDUP((REGENERANTS!H33*REGENERANTS!$CF$20)*'[1]Paramètres Généraux'!$M$15,-1),REGENERANTS!H33*REGENERANTS!$CF$20)),"nd") | DQ33: =SUM(CN33:DP33) | DR33: =SUM(CV33:DP33) | DS33: =IFERROR((IF(AND($F33="Produit Vente",CO33>0),VLOOKUP($C33,'[1]Paramètres Articles'!$B:$H,7,FALSE)*$CO33)*(1-20%)),0) | DT33: =IFERROR((IF(AND($F33="Produit Vente",DR33>0),VLOOKUP($C33,'[1]Paramètres Articles'!$B:$H,6,FALSE)*$DR33)*(1-15%)),0) | DU33: =IFERROR(DQ33*J33,0)
B34: =IF(C34="",0,COUNTIFS($B$22:B33,">"&0)+1) | C34: 1020720 | D34: =IFERROR(IF($C34="","",VLOOKUP($C34,'[1]Paramètres Articles'!$B:$G,2,FALSE)),"Non Trouvé") | E34: =IFERROR(IF($C34="","",_xlfn.XLOOKUP(REGENERANTS!$C34,'[1]New Base PA'!$F:$F,'[1]New Base PA'!$D:$D,"Not Found",0)),"Non Trouvé") | F34: Produit Vente | H34: 8 | J34: =IFERROR(IF($C34="","",VLOOKUP($C34,'[1]New Base PA'!$F:$J,5,FALSE)),"Non Trouvé") | K34: =IFERROR(IF($C34="","",$J34*$H34),"Non Trouvé") | M34: =IFERROR(IF(AND($F34="Produit Vente",H34>0),VLOOKUP($C34,'[1]Paramètres Articles'!$B:$G,6,FALSE),0),"Non Trouvé") | N34: =IFERROR(IF($C34="","",$M34*$H34),"Non Trouvé") | P34: 0.15 | R34: =IFERROR(IF($C34="","",$N34*(1-$P34)),"Non Trouvé") | T34: =IFERROR(IF($C34="","",VLOOKUP($C34,'[1]Paramètres Articles'!$B:$H,7,FALSE)),"Non Trouvé") | V34: =IFERROR(IF($C34="","",IF($P34="","",$T34*(1-$P34))),"Non Trouvé") | X34: =IFERROR(T34-V34,"") | Z34: =IFERROR(IF(OR(T34=0,T34=""),0,T34*H34),"Non Trouvé") | AB34: =AB33 | AC34: =AC33 | AD34: =IFERROR(IF($C34="","",IF($P$15="Cascade",$R34*(1-AC34)*AB34,IF($P$15="Additionnelle",($N34-($N34*($P34+AC34)))*AB34))),"Non Trouvé") | AG34: =AG33 | AH34: =AH33 | AI34: =IFERROR(IF($C34="","",IF($P$15="Cascade",$R34*(1-AH34)*AG34,IF($P$15="Additionnelle",($N34-($N34*($P34+AH34)))*AG34))),"Non Trouvé") | AL34: =AL33 | AM34: =AM33 | AN34: =IFERROR(IF($C34="","",IF($P$15="Cascade",$R34*(1-AM34)*AL34,IF($P$15="Additionnelle",($N34-($N34*($P34+AM34)))*AL34))),"Non Trouvé") | AQ34: =AQ33 | AR34: =AR33 | AS34: =IFERROR(IF($C34="","",IF($P$15="Cascade",$R34*(1-AR34)*AQ34,IF($P$15="Additionnelle",($N34-($N34*($P34+AR34)))*AQ34))),"Non Trouvé") | AV34: =AV33 | AW34: =AW33 | AX34: =IFERROR(IF($C34="","",IF($P$15="Cascade",$R34*(1-AW34)*AV34,IF($P$15="Additionnelle",($N34-($N34*($P34+AW34)))*AV34))),"Non Trouvé") | BA34: =BA33 | BB34: =BB33 | BC34: =IFERROR(IF($C34="","",IF($P$15="Cascade",$R34*(1-BB34)*BA34,IF($P$15="Additionnelle",($N34-($N34*($P34+BB34)))*BA34))),"Non Trouvé") | BF34: =BF33 | BG34: =BG33 | BH34: =IFERROR(IF($C34="","",IF($P$15="Cascade",$R34*(1-BG34)*BF34,IF($P$15="Additionnelle",($N34-($N34*($P34+BG34)))*BF34))),"Non Trouvé") | BK34: =BK33 | BL34: =BL33 | BM34: =IFERROR(IF($C34="","",IF($P$15="Cascade",$R34*(1-BL34)*BK34,IF($P$15="Additionnelle",($N34-($N34*($P34+BL34)))*BK34))),"Non Trouvé") | BP34: =BP33 | BQ34: =BQ33 | BR34: =IFERROR(IF($C34="","",IF($P$15="Cascade",$R34*(1-BQ34)*BP34,IF($P$15="Additionnelle",($N34-($N34*($P34+BQ34)))*BP34))),"Non Trouvé") | BU34: =BU33 | BV34: =BV33 | BW34: =IFERROR(IF($C34="","",IF($P$15="Cascade",$R34*(1-BV34)*BU34,IF($P$15="Additionnelle",($N34-($N34*($P34+BV34)))*BU34))),"Non Trouvé") | BZ34: =BZ33 | CA34: =CA33 | CB34: =IFERROR(IF($C34="","",IF($P$15="Cascade",$R34*(1-CA34)*BZ34,IF($P$15="Additionnelle",($N34-($N34*($P34+CA34)))*BZ34))),"Non Trouvé") | CG34: Retail | CK34: =IFERROR(IF(F34='[1]Paramètres Généraux'!$K$12,ROUNDUP((REGENERANTS!H34*REGENERANTS!$CF$20)*'[1]Paramètres Généraux'!$M$12,-1),IF(F34='[1]Paramètres Généraux'!$K$15,ROUNDUP((REGENERANTS!H34*REGENERANTS!$CF$20)*'[1]Paramètres Généraux'!$M$15,-1),REGENERANTS!H34*REGENERANTS!$CF$20)),"nd") | DQ34: =SUM(CN34:DP34) | DR34: =SUM(CV34:DP34) | DS34: =IFERROR((IF(AND($F34="Produit Vente",CO34>0),VLOOKUP($C34,'[1]Paramètres Articles'!$B:$H,7,FALSE)*$CO34)*(1-20%)),0) | DT34: =IFERROR((IF(AND($F34="Produit Vente",DR34>0),VLOOKUP($C34,'[1]Paramètres Articles'!$B:$H,6,FALSE)*$DR34)*(1-15%)),0) | DU34: =IFERROR(DQ34*J34,0)
