Workbook

Sheet Proposition template
A3: TG VIP
A4: Nombre d'offres
A5: Nombre de produits | B5: =SUM(E17:E29) -> 0
M6: RETAIL | S6: INSTITUT | AB6: Retail + Institut
M8: Ambassadeur | O8: Compagnon | Q8: Challenger | S8: Rose | U8: Prunelier | W8: Anthylide | Y8: Calendula | AB8: Total
M9: % Offres | O9: % Offres | Q9: % Offres | S9: % Offres | U9: % Offres | W9: % Offres
M10: Remise | N10: 0.17 | O10: Remise | P10: 0.13 | Q10: Remise | R10: 0.08 | S10: Remise | T10: 0.325 | U10: Remise | V10: 0.3 | W10: Remise | X10: 0.28 | Y10: Remise | Z10: 0.25
M11: Nb Offres | N11: =N9*$B$4 -> 0 | O11: Nb Offres | P11: =P9*$B$4 -> 0 | Q11: Nb Offres | R11: =R9*$B$4 -> 0 | S11: Nb Offres | T11: =T9*$B$4 -> 0 | U11: Nb Offres | V11: =V9*$B$4 -> 0 | W11: Nb Offres | X11: =X9*$B$4 -> 0 | Y11: Nb Offres | Z11: =Z9*$B$4 -> 0
E12: Pdt dans offre | F12: Coût achat unitaire | G12: Coûts achats total | H12: Tarif revendeur unitaire | I12: Remise additionnelle | J12: PPC | K12: PPC Remisé | L12: Montant BRI | M12: CA | N12: Marges | O12: CA | P12: Marges | Q12: CA | R12: Marges | S12: CA | T12: Marges | U12: CA | V12: Marges | W12: CA | X12: Marges | Y12: CA | Z12: Marges | AB12: Nbrs Offres planifiées | AC12: CA | AD12: Marges
A13: Code article | B13: Libellé article | C13: Code à barres (EAN) | D13: Typ. Prod | E13: '# | F13: '€ | G13: '€ | H13: '€ | I13: '€ | J13: '€ | K13: '€ | L13: '€ | M13: '€ | N13: '€ | O13: '€ | P13: '€ | Q13: '€ | R13: '€ | S13: '€ | T13: '€ | U13: '€ | V13: '€ | W13: '€ | X13: '€ | Y13: '€ | Z13: '€ | AB13: '# | AC13: '€ | AD13: '€
A15: Synthèse | E15: =IFERROR(SUMIFS(E17:E36,D17:D36,"Produit Vente"),"Non trouvé") -> 0 | G15: =IFERROR(SUM(G17:G36),"Non Trouvé") -> 0 | M15: =SUM(M17:M36) -> 0 | N15: =SUM(N17:N36) -> 0 | O15: =SUM(O17:O36) -> 0 | P15: =SUM(P17:P36) -> 0 | Q15: =SUM(Q17:Q36) -> 0 | R15: =SUM(R17:R36) -> 0 | S15: =SUM(S17:S36) -> 0 | T15: =SUM(T17:T36) -> 0 | ... Z15: =SUM(Z17:Z36) -> 0 | AB15: =B4 -> 0 | AC15: =Y15+W15+U15+S15+O15+M15+Q15 -> 0 | AD15: =Z15+X15+V15+T15+P15+N15+R15 -> 0
B17: =IFERROR(VLOOKUP(A17,Mapping!$A:$F,2,FALSE),"") | C17: =IFERROR(VLOOKUP(A17,Mapping!$A:$F,3,FALSE),"") | F17: =IFERROR(VLOOKUP(A17,Mapping!$A:$F,4,FALSE),0) -> 0 | G17: =E17*F17 -> 0 | H17: =IFERROR(VLOOKUP(A17,Mapping!$A:$F,5,FALSE),0) -> 0 | J17: =IFERROR(VLOOKUP(A17,Mapping!$A:$F,6,FALSE),0) -> 0 | K17: =J17*(1-I17) -> 0 | L17: =IFERROR(J17-K17,"") -> 0 | M17: =E17*H17*(1-I17)*$N$11*(1-$N$10) -> 0 | N17: =M17-E17*F17*$N$11 -> 0 | O17: =E17*H17*(1-I17)*$P$11*(1-$P$10) -> 0 | P17: =O17-E17*F17*$P$11 -> 0 | Q17: =E17*H17*(1-I17)*$R$11*(1-$R$10) -> 0 | R17: =Q17-E17*F17*$R$11 -> 0 | S17: =E17*H17*(1-I17)*$T$11*(1-$T$10) -> 0 | T17: =S17-E17*F17*$T$11 -> 0 | U17: =E17*H17*(1-I17)*$V$11*(1-$V$10) -> 0 | V17: =U17-E17*F17*$V$11 -> 0 | W17: =E17*H17*(1-I17)*$X$11*(1-$X$10) -> 0 | X17: =W17-E17*F17*$X$11 -> 0 | Y17: =E17*H17*(1-I17)*$Z$11*(1-$Z$10) -> 0 | Z17: =Y17-E17*F17*$Z$11 -> 0
B18: =IFERROR(VLOOKUP(A18,Mapping!$A:$F,2,FALSE),"") | C18: =IFERROR(VLOOKUP(A18,Mapping!$A:$F,3,FALSE),"") | F18: =IFERROR(VLOOKUP(A18,Mapping!$A:$F,4,FALSE),0) -> 0 | G18: =E18*F18 -> 0 | H18: =IFERROR(VLOOKUP(A18,Mapping!$A:$F,5,FALSE),0) -> 0 | J18: =IFERROR(VLOOKUP(A18,Mapping!$A:$F,6,FALSE),0) -> 0 | K18: =J18*(1-I18) -> 0 | L18: =IFERROR(J18-K18,"") -> 0 | M18: =E18*H18*(1-I18)*$N$11*(1-$N$10) -> 0 | N18: =M18-E18*F18*$N$11 -> 0 | O18: =E18*H18*(1-I18)*$P$11*(1-$P$10) -> 0 | P18: =O18-E18*F18*$P$11 -> 0 | Q18: =E18*H18*(1-I18)*$R$11*(1-$R$10) -> 0 | R18: =Q18-E18*F18*$R$11 -> 0 | S18: =E18*H18*(1-I18)*$T$11*(1-$T$10) -> 0 | T18: =S18-E18*F18*$T$11 -> 0 | U18: =E18*H18*(1-I18)*$V$11*(1-$V$10) -> 0 | V18: =U18-E18*F18*$V$11 -> 0 | W18: =E18*H18*(1-I18)*$X$11*(1-$X$10) -> 0 | X18: =W18-E18*F18*$X$11 -> 0 | Y18: =E18*H18*(1-I18)*$Z$11*(1-$Z$10) -> 0 | Z18: =Y18-E18*F18*$Z$11 -> 0 | AC18: Prix Offre Moy. Remisé : | AD18: =AC15/AB15 -> #DIV/0!
B19: =IFERROR(VLOOKUP(A19,Mapping!$A:$F,2,FALSE),"") | C19: =IFERROR(VLOOKUP(A19,Mapping!$A:$F,3,FALSE),"") | F19: =IFERROR(VLOOKUP(A19,Mapping!$A:$F,4,FALSE),0) -> 0 | G19: =E19*F19 -> 0 | H19: =IFERROR(VLOOKUP(A19,Mapping!$A:$F,5,FALSE),0) -> 0 | J19: =IFERROR(VLOOKUP(A19,Mapping!$A:$F,6,FALSE),0) -> 0 | K19: =J19*(1-I19) -> 0 | L19: =IFERROR(J19-K19,"") -> 0 | M19: =E19*H19*(1-I19)*$N$11*(1-$N$10) -> 0 | N19: =M19-E19*F19*$N$11 -> 0 | O19: =E19*H19*(1-I19)*$P$11*(1-$P$10) -> 0 | P19: =O19-E19*F19*$P$11 -> 0 | Q19: =E19*H19*(1-I19)*$R$11*(1-$R$10) -> 0 | R19: =Q19-E19*F19*$R$11 -> 0 | S19: =E19*H19*(1-I19)*$T$11*(1-$T$10) -> 0 | T19: =S19-E19*F19*$T$11 -> 0 | U19: =E19*H19*(1-I19)*$V$11*(1-$V$10) -> 0 | V19: =U19-E19*F19*$V$11 -> 0 | W19: =E19*H19*(1-I19)*$X$11*(1-$X$10) -> 0 | X19: =W19-E19*F19*$X$11 -> 0 | Y19: =E19*H19*(1-I19)*$Z$11*(1-$Z$10) -> 0 | Z19: =Y19-E19*F19*$Z$11 -> 0 | AC19: Poids Gratuités achats : | AD19: =SUM(AD21:AD24) -> #DIV/0!
B20: =IFERROR(VLOOKUP(A20,Mapping!$A:$F,2,FALSE),"") | C20: =IFERROR(VLOOKUP(A20,Mapping!$A:$F,3,FALSE),"") | F20: =IFERROR(VLOOKUP(A20,Mapping!$A:$F,4,FALSE),0) -> 0 | G20: =E20*F20 -> 0 | H20: =IFERROR(VLOOKUP(A20,Mapping!$A:$F,5,FALSE),0) -> 0 | J20: =IFERROR(VLOOKUP(A20,Mapping!$A:$F,6,FALSE),0) -> 0 | K20: =J20*(1-I20) -> 0 | L20: =IFERROR(J20-K20,"") -> 0 | M20: =E20*H20*(1-I20)*$N$11*(1-$N$10) -> 0 | N20: =M20-E20*F20*$N$11 -> 0 | O20: =E20*H20*(1-I20)*$P$11*(1-$P$10) -> 0 | P20: =O20-E20*F20*$P$11 -> 0 | Q20: =E20*H20*(1-I20)*$R$11*(1-$R$10) -> 0 | R20: =Q20-E20*F20*$R$11 -> 0 | S20: =E20*H20*(1-I20)*$T$11*(1-$T$10) -> 0 | T20: =S20-E20*F20*$T$11 -> 0 | U20: =E20*H20*(1-I20)*$V$11*(1-$V$10) -> 0 | V20: =U20-E20*F20*$V$11 -> 0 | W20: =E20*H20*(1-I20)*$X$11*(1-$X$10) -> 0 | X20: =W20-E20*F20*$X$11 -> 0 | Y20: =E20*H20*(1-I20)*$Z$11*(1-$Z$10) -> 0 | Z20: =Y20-E20*F20*$Z$11 -> 0
B21: =IFERROR(VLOOKUP(A21,Mapping!$A:$F,2,FALSE),"") | C21: =IFERROR(VLOOKUP(A21,Mapping!$A:$F,3,FALSE),"") | F21: =IFERROR(VLOOKUP(A21,Mapping!$A:$F,4,FALSE),0) -> 0 | G21: =E21*F21 -> 0 | H21: =IFERROR(VLOOKUP(A21,Mapping!$A:$F,5,FALSE),0) -> 0 | J21: =IFERROR(VLOOKUP(A21,Mapping!$A:$F,6,FALSE),0) -> 0 | K21: =J21*(1-I21) -> 0 | L21: =IFERROR(J21-K21,"") -> 0 | M21: =E21*H21*(1-I21)*$N$11*(1-$N$10) -> 0 | N21: =M21-E21*F21*$N$11 -> 0 | O21: =E21*H21*(1-I21)*$P$11*(1-$P$10) -> 0 | P21: =O21-E21*F21*$P$11 -> 0 | Q21: =E21*H21*(1-I21)*$R$11*(1-$R$10) -> 0 | R21: =Q21-E21*F21*$R$11 -> 0 | S21: =E21*H21*(1-I21)*$T$11*(1-$T$10) -> 0 | T21: =S21-E21*F21*$T$11 -> 0 | U21: =E21*H21*(1-I21)*$V$11*(1-$V$10) -> 0 | V21: =U21-E21*F21*$V$11 -> 0 | W21: =E21*H21*(1-I21)*$X$11*(1-$X$10) -> 0 | X21: =W21-E21*F21*$X$11 -> 0 | Y21: =E21*H21*(1-I21)*$Z$11*(1-$Z$10) -> 0 | Z21: =Y21-E21*F21*$Z$11 -> 0 | AC21: UG | AD21: =SUMIF($D$16:$D$36,AC21,$G$16:$G$36)/$AC$15 -> #DIV/0!
B22: =IFERROR(VLOOKUP(A22,Mapping!$A:$F,2,FALSE),"") | C22: =IFERROR(VLOOKUP(A22,Mapping!$A:$F,3,FALSE),"") | F22: =IFERROR(VLOOKUP(A22,Mapping!$A:$F,4,FALSE),0) -> 0 | G22: =E22*F22 -> 0 | H22: =IFERROR(VLOOKUP(A22,Mapping!$A:$F,5,FALSE),0) -> 0 | J22: =IFERROR(VLOOKUP(A22,Mapping!$A:$F,6,FALSE),0) -> 0 | K22: =J22*(1-I22) -> 0 | L22: =IFERROR(J22-K22,"") -> 0 | M22: =E22*H22*(1-I22)*$N$11*(1-$N$10) -> 0 | N22: =M22-E22*F22*$N$11 -> 0 | O22: =E22*H22*(1-I22)*$P$11*(1-$P$10) -> 0 | P22: =O22-E22*F22*$P$11 -> 0 | Q22: =E22*H22*(1-I22)*$R$11*(1-$R$10) -> 0 | R22: =Q22-E22*F22*$R$11 -> 0 | S22: =E22*H22*(1-I22)*$T$11*(1-$T$10) -> 0 | T22: =S22-E22*F22*$T$11 -> 0 | U22: =E22*H22*(1-I22)*$V$11*(1-$V$10) -> 0 | V22: =U22-E22*F22*$V$11 -> 0 | W22: =E22*H22*(1-I22)*$X$11*(1-$X$10) -> 0 | X22: =W22-E22*F22*$X$11 -> 0 | Y22: =E22*H22*(1-I22)*$Z$11*(1-$Z$10) -> 0 | Z22: =Y22-E22*F22*$Z$11 -> 0 | AC22: PLV | AD22: =SUMIF($D$16:$D$36,AC22,$G$16:$G$36)/$AC$15 -> #DIV/0!
B23: =IFERROR(VLOOKUP(A23,Mapping!$A:$F,2,FALSE),"") | C23: =IFERROR(VLOOKUP(A23,Mapping!$A:$F,3,FALSE),"") | F23: =IFERROR(VLOOKUP(A23,Mapping!$A:$F,4,FALSE),0) -> 0 | G23: =E23*F23 -> 0 | H23: =IFERROR(VLOOKUP(A23,Mapping!$A:$F,5,FALSE),0) -> 0 | J23: =IFERROR(VLOOKUP(A23,Mapping!$A:$F,6,FALSE),0) -> 0 | K23: =J23*(1-I23) -> 0 | L23: =IFERROR(J23-K23,"") -> 0 | M23: =E23*H23*(1-I23)*$N$11*(1-$N$10) -> 0 | N23: =M23-E23*F23*$N$11 -> 0 | O23: =E23*H23*(1-I23)*$P$11*(1-$P$10) -> 0 | P23: =O23-E23*F23*$P$11 -> 0 | Q23: =E23*H23*(1-I23)*$R$11*(1-$R$10) -> 0 | R23: =Q23-E23*F23*$R$11 -> 0 | S23: =E23*H23*(1-I23)*$T$11*(1-$T$10) -> 0 | T23: =S23-E23*F23*$T$11 -> 0 | U23: =E23*H23*(1-I23)*$V$11*(1-$V$10) -> 0 | V23: =U23-E23*F23*$V$11 -> 0 | W23: =E23*H23*(1-I23)*$X$11*(1-$X$10) -> 0 | X23: =W23-E23*F23*$X$11 -> 0 | Y23: =E23*H23*(1-I23)*$Z$11*(1-$Z$10) -> 0 | Z23: =Y23-E23*F23*$Z$11 -> 0 | AC23: Echantillon | AD23: =SUMIF($D$16:$D$36,AC23,$G$16:$G$36)/$AC$15 -> #DIV/0!
B24: =IFERROR(VLOOKUP(A24,Mapping!$A:$F,2,FALSE),"") | C24: =IFERROR(VLOOKUP(A24,Mapping!$A:$F,3,FALSE),"") | F24: =IFERROR(VLOOKUP(A24,Mapping!$A:$F,4,FALSE),0) -> 0 | G24: =E24*F24 -> 0 | H24: =IFERROR(VLOOKUP(A24,Mapping!$A:$F,5,FALSE),0) -> 0 | J24: =IFERROR(VLOOKUP(A24,Mapping!$A:$F,6,FALSE),0) -> 0 | K24: =J24*(1-I24) -> 0 | L24: =IFERROR(J24-K24,"") -> 0 | M24: =E24*H24*(1-I24)*$N$11*(1-$N$10) -> 0 | N24: =M24-E24*F24*$N$11 -> 0 | O24: =E24*H24*(1-I24)*$P$11*(1-$P$10) -> 0 | P24: =O24-E24*F24*$P$11 -> 0 | Q24: =E24*H24*(1-I24)*$R$11*(1-$R$10) -> 0 | R24: =Q24-E24*F24*$R$11 -> 0 | S24: =E24*H24*(1-I24)*$T$11*(1-$T$10) -> 0 | T24: =S24-E24*F24*$T$11 -> 0 | U24: =E24*H24*(1-I24)*$V$11*(1-$V$10) -> 0 | V24: =U24-E24*F24*$V$11 -> 0 | W24: =E24*H24*(1-I24)*$X$11*(1-$X$10) -> 0 | X24: =W24-E24*F24*$X$11 -> 0 | Y24: =E24*H24*(1-I24)*$Z$11*(1-$Z$10) -> 0 | Z24: =Y24-E24*F24*$Z$11 -> 0 | AC24: Testeur | AD24: =SUMIF($D$16:$D$36,AC24,$G$16:$G$36)/$AC$15 -> #DIV/0!
B25: =IFERROR(VLOOKUP(A25,Mapping!$A:$F,2,FALSE),"") | C25: =IFERROR(VLOOKUP(A25,Mapping!$A:$F,3,FALSE),"") | F25: =IFERROR(VLOOKUP(A25,Mapping!$A:$F,4,FALSE),0) -> 0 | G25: =E25*F25 -> 0 | H25: =IFERROR(VLOOKUP(A25,Mapping!$A:$F,5,FALSE),0) -> 0 | J25: =IFERROR(VLOOKUP(A25,Mapping!$A:$F,6,FALSE),0) -> 0 | K25: =J25*(1-I25) -> 0 | L25: =IFERROR(J25-K25,"") -> 0 | M25: =E25*H25*(1-I25)*$N$11*(1-$N$10) -> 0 | N25: =M25-E25*F25*$N$11 -> 0 | O25: =E25*H25*(1-I25)*$P$11*(1-$P$10) -> 0 | P25: =O25-E25*F25*$P$11 -> 0 | Q25: =E25*H25*(1-I25)*$R$11*(1-$R$10) -> 0 | R25: =Q25-E25*F25*$R$11 -> 0 | S25: =E25*H25*(1-I25)*$T$11*(1-$T$10) -> 0 | T25: =S25-E25*F25*$T$11 -> 0 | U25: =E25*H25*(1-I25)*$V$11*(1-$V$10) -> 0 | V25: =U25-E25*F25*$V$11 -> 0 | W25: =E25*H25*(1-I25)*$X$11*(1-$X$10) -> 0 | X25: =W25-E25*F25*$X$11 -> 0 | Y25: =E25*H25*(1-I25)*$Z$11*(1-$Z$10) -> 0 | Z25: =Y25-E25*F25*$Z$11 -> 0
B26: =IFERROR(VLOOKUP(A26,Mapping!$A:$F,2,FALSE),"") | C26: =IFERROR(VLOOKUP(A26,Mapping!$A:$F,3,FALSE),"") | F26: =IFERROR(VLOOKUP(A26,Mapping!$A:$F,4,FALSE),0) -> 0 | G26: =E26*F26 -> 0 | H26: =IFERROR(VLOOKUP(A26,Mapping!$A:$F,5,FALSE),0) -> 0 | J26: =IFERROR(VLOOKUP(A26,Mapping!$A:$F,6,FALSE),0) -> 0 | K26: =J26*(1-I26) -> 0 | L26: =IFERROR(J26-K26,"") -> 0 | M26: =E26*H26*(1-I26)*$N$11*(1-$N$10) -> 0 | N26: =M26-E26*F26*$N$11 -> 0 | O26: =E26*H26*(1-I26)*$P$11*(1-$P$10) -> 0 | P26: =O26-E26*F26*$P$11 -> 0 | Q26: =E26*H26*(1-I26)*$R$11*(1-$R$10) -> 0 | R26: =Q26-E26*F26*$R$11 -> 0 | S26: =E26*H26*(1-I26)*$T$11*(1-$T$10) -> 0 | T26: =S26-E26*F26*$T$11 -> 0 | U26: =E26*H26*(1-I26)*$V$11*(1-$V$10) -> 0 | V26: =U26-E26*F26*$V$11 -> 0 | W26: =E26*H26*(1-I26)*$X$11*(1-$X$10) -> 0 | X26: =W26-E26*F26*$X$11 -> 0 | Y26: =E26*H26*(1-I26)*$Z$11*(1-$Z$10) -> 0 | Z26: =Y26-E26*F26*$Z$11 -> 0
B27: =IFERROR(VLOOKUP(A27,Mapping!$A:$F,2,FALSE),"") | C27: =IFERROR(VLOOKUP(A27,Mapping!$A:$F,3,FALSE),"") | F27: =IFERROR(VLOOKUP(A27,Mapping!$A:$F,4,FALSE),0) -> 0 | G27: =E27*F27 -> 0 | H27: =IFERROR(VLOOKUP(A27,Mapping!$A:$F,5,FALSE),0) -> 0 | J27: =IFERROR(VLOOKUP(A27,Mapping!$A:$F,6,FALSE),0) -> 0 | K27: =J27*(1-I27) -> 0 | L27: =IFERROR(J27-K27,"") -> 0 | M27: =E27*H27*(1-I27)*$N$11*(1-$N$10) -> 0 | N27: =M27-E27*F27*$N$11 -> 0 | O27: =E27*H27*(1-I27)*$P$11*(1-$P$10) -> 0 | P27: =O27-E27*F27*$P$11 -> 0 | Q27: =E27*H27*(1-I27)*$R$11*(1-$R$10) -> 0 | R27: =Q27-E27*F27*$R$11 -> 0 | S27: =E27*H27*(1-I27)*$T$11*(1-$T$10) -> 0 | T27: =S27-E27*F27*$T$11 -> 0 | U27: =E27*H27*(1-I27)*$V$11*(1-$V$10) -> 0 | V27: =U27-E27*F27*$V$11 -> 0 | W27: =E27*H27*(1-I27)*$X$11*(1-$X$10) -> 0 | X27: =W27-E27*F27*$X$11 -> 0 | Y27: =E27*H27*(1-I27)*$Z$11*(1-$Z$10) -> 0 | Z27: =Y27-E27*F27*$Z$11 -> 0
B28: =IFERROR(VLOOKUP(A28,Mapping!$A:$F,2,FALSE),"") | C28: =IFERROR(VLOOKUP(A28,Mapping!$A:$F,3,FALSE),"") | F28: =IFERROR(VLOOKUP(A28,Mapping!$A:$F,4,FALSE),0) -> 0 | G28: =E28*F28 -> 0 | H28: =IFERROR(VLOOKUP(A28,Mapping!$A:$F,5,FALSE),0) -> 0 | J28: =IFERROR(VLOOKUP(A28,Mapping!$A:$F,6,FALSE),0) -> 0 | K28: =J28*(1-I28) -> 0 | L28: =IFERROR(J28-K28,"") -> 0 | M28: =E28*H28*(1-I28)*$N$11*(1-$N$10) -> 0 | N28: =M28-E28*F28*$N$11 -> 0 | O28: =E28*H28*(1-I28)*$P$11*(1-$P$10) -> 0 | P28: =O28-E28*F28*$P$11 -> 0 | Q28: =E28*H28*(1-I28)*$R$11*(1-$R$10) -> 0 | R28: =Q28-E28*F28*$R$11 -> 0 | S28: =E28*H28*(1-I28)*$T$11*(1-$T$10) -> 0 | T28: =S28-E28*F28*$T$11 -> 0 | U28: =E28*H28*(1-I28)*$V$11*(1-$V$10) -> 0 | V28: =U28-E28*F28*$V$11 -> 0 | W28: =E28*H28*(1-I28)*$X$11*(1-$X$10) -> 0 | X28: =W28-E28*F28*$X$11 -> 0 | Y28: =E28*H28*(1-I28)*$Z$11*(1-$Z$10) -> 0 | Z28: =Y28-E28*F28*$Z$11 -> 0
B29: =IFERROR(VLOOKUP(A29,Mapping!$A:$F,2,FALSE),"") | C29: =IFERROR(VLOOKUP(A29,Mapping!$A:$F,3,FALSE),"") | F29: =IFERROR(VLOOKUP(A29,Mapping!$A:$F,4,FALSE),0) -> 0 | G29: =E29*F29 -> 0 | H29: =IFERROR(VLOOKUP(A29,Mapping!$A:$F,5,FALSE),0) -> 0 | J29: =IFERROR(VLOOKUP(A29,Mapping!$A:$F,6,FALSE),0) -> 0 | K29: =J29*(1-I29) -> 0 | L29: =IFERROR(J29-K29,"") -> 0 | M29: =E29*H29*(1-I29)*$N$11*(1-$N$10) -> 0 | N29: =M29-E29*F29*$N$11 -> 0 | O29: =E29*H29*(1-I29)*$P$11*(1-$P$10) -> 0 | P29: =O29-E29*F29*$P$11 -> 0 | Q29: =E29*H29*(1-I29)*$R$11*(1-$R$10) -> 0 | R29: =Q29-E29*F29*$R$11 -> 0 | S29: =E29*H29*(1-I29)*$T$11*(1-$T$10) -> 0 | T29: =S29-E29*F29*$T$11 -> 0 | U29: =E29*H29*(1-I29)*$V$11*(1-$V$10) -> 0 | V29: =U29-E29*F29*$V$11 -> 0 | W29: =E29*H29*(1-I29)*$X$11*(1-$X$10) -> 0 | X29: =W29-E29*F29*$X$11 -> 0 | Y29: =E29*H29*(1-I29)*$Z$11*(1-$Z$10) -> 0 | Z29: =Y29-E29*F29*$Z$11 -> 0
B30: =IFERROR(VLOOKUP(A30,Mapping!$A:$F,2,FALSE),"") | C30: =IFERROR(VLOOKUP(A30,Mapping!$A:$F,3,FALSE),"") | F30: =IFERROR(VLOOKUP(A30,Mapping!$A:$F,4,FALSE),0) -> 0 | G30: =E30*F30 -> 0 | H30: =IFERROR(VLOOKUP(A30,Mapping!$A:$F,5,FALSE),0) -> 0 | J30: =IFERROR(VLOOKUP(A30,Mapping!$A:$F,6,FALSE),0) -> 0 | K30: =J30*(1-I30) -> 0 | L30: =IFERROR(J30-K30,"") -> 0 | M30: =E30*H30*(1-I30)*$N$11*(1-$N$10) -> 0 | N30: =M30-E30*F30*$N$11 -> 0 | O30: =E30*H30*(1-I30)*$P$11*(1-$P$10) -> 0 | P30: =O30-E30*F30*$P$11 -> 0 | Q30: =E30*H30*(1-I30)*$R$11*(1-$R$10) -> 0 | R30: =Q30-E30*F30*$R$11 -> 0 | S30: =E30*H30*(1-I30)*$T$11*(1-$T$10) -> 0 | T30: =S30-E30*F30*$T$11 -> 0 | U30: =E30*H30*(1-I30)*$V$11*(1-$V$10) -> 0 | V30: =U30-E30*F30*$V$11 -> 0 | W30: =E30*H30*(1-I30)*$X$11*(1-$X$10) -> 0 | X30: =W30-E30*F30*$X$11 -> 0 | Y30: =E30*H30*(1-I30)*$Z$11*(1-$Z$10) -> 0 | Z30: =Y30-E30*F30*$Z$11 -> 0
B31: =IFERROR(VLOOKUP(A31,Mapping!$A:$F,2,FALSE),"") | C31: =IFERROR(VLOOKUP(A31,Mapping!$A:$F,3,FALSE),"") | F31: =IFERROR(VLOOKUP(A31,Mapping!$A:$F,4,FALSE),0) -> 0 | G31: =E31*F31 -> 0 | H31: =IFERROR(VLOOKUP(A31,Mapping!$A:$F,5,FALSE),0) -> 0 | J31: =IFERROR(VLOOKUP(A31,Mapping!$A:$F,6,FALSE),0) -> 0 | K31: =J31*(1-I31) -> 0 | L31: =IFERROR(J31-K31,"") -> 0 | M31: =E31*H31*(1-I31)*$N$11*(1-$N$10) -> 0 | N31: =M31-E31*F31*$N$11 -> 0 | O31: =E31*H31*(1-I31)*$P$11*(1-$P$10) -> 0 | P31: =O31-E31*F31*$P$11 -> 0 | Q31: =E31*H31*(1-I31)*$R$11*(1-$R$10) -> 0 | R31: =Q31-E31*F31*$R$11 -> 0 | S31: =E31*H31*(1-I31)*$T$11*(1-$T$10) -> 0 | T31: =S31-E31*F31*$T$11 -> 0 | U31: =E31*H31*(1-I31)*$V$11*(1-$V$10) -> 0 | V31: =U31-E31*F31*$V$11 -> 0 | W31: =E31*H31*(1-I31)*$X$11*(1-$X$10) -> 0 | X31: =W31-E31*F31*$X$11 -> 0 | Y31: =E31*H31*(1-I31)*$Z$11*(1-$Z$10) -> 0 | Z31: =Y31-E31*F31*$Z$11 -> 0
B32: =IFERROR(VLOOKUP(A32,Mapping!$A:$F,2,FALSE),"") | C32: =IFERROR(VLOOKUP(A32,Mapping!$A:$F,3,FALSE),"") | F32: =IFERROR(VLOOKUP(A32,Mapping!$A:$F,4,FALSE),0) -> 0 | G32: =E32*F32 -> 0 | H32: =IFERROR(VLOOKUP(A32,Mapping!$A:$F,5,FALSE),0) -> 0 | J32: =IFERROR(VLOOKUP(A32,Mapping!$A:$F,6,FALSE),0) -> 0 | K32: =J32*(1-I32) -> 0 | L32: =IFERROR(J32-K32,"") -> 0 | M32: =E32*H32*(1-I32)*$N$11*(1-$N$10) -> 0 | N32: =M32-E32*F32*$N$11 -> 0 | O32: =E32*H32*(1-I32)*$P$11*(1-$P$10) -> 0 | P32: =O32-E32*F32*$P$11 -> 0 | Q32: =E32*H32*(1-I32)*$R$11*(1-$R$10) -> 0 | R32: =Q32-E32*F32*$R$11 -> 0 | S32: =E32*H32*(1-I32)*$T$11*(1-$T$10) -> 0 | T32: =S32-E32*F32*$T$11 -> 0 | U32: =E32*H32*(1-I32)*$V$11*(1-$V$10) -> 0 | V32: =U32-E32*F32*$V$11 -> 0 | W32: =E32*H32*(1-I32)*$X$11*(1-$X$10) -> 0 | X32: =W32-E32*F32*$X$11 -> 0 | Y32: =E32*H32*(1-I32)*$Z$11*(1-$Z$10) -> 0 | Z32: =Y32-E32*F32*$Z$11 -> 0
B33: =IFERROR(VLOOKUP(A33,Mapping!$A:$F,2,FALSE),"") | C33: =IFERROR(VLOOKUP(A33,Mapping!$A:$F,3,FALSE),"") | F33: =IFERROR(VLOOKUP(A33,Mapping!$A:$F,4,FALSE),0) -> 0 | G33: =E33*F33 -> 0 | H33: =IFERROR(VLOOKUP(A33,Mapping!$A:$F,5,FALSE),0) -> 0 | J33: =IFERROR(VLOOKUP(A33,Mapping!$A:$F,6,FALSE),0) -> 0 | K33: =J33*(1-I33) -> 0 | L33: =IFERROR(J33-K33,"") -> 0 | M33: =E33*H33*(1-I33)*$N$11*(1-$N$10) -> 0 | N33: =M33-E33*F33*$N$11 -> 0 | O33: =E33*H33*(1-I33)*$P$11*(1-$P$10) -> 0 | P33: =O33-E33*F33*$P$11 -> 0 | Q33: =E33*H33*(1-I33)*$R$11*(1-$R$10) -> 0 | R33: =Q33-E33*F33*$R$11 -> 0 | S33: =E33*H33*(1-I33)*$T$11*(1-$T$10) -> 0 | T33: =S33-E33*F33*$T$11 -> 0 | U33: =E33*H33*(1-I33)*$V$11*(1-$V$10) -> 0 | V33: =U33-E33*F33*$V$11 -> 0 | W33: =E33*H33*(1-I33)*$X$11*(1-$X$10) -> 0 | X33: =W33-E33*F33*$X$11 -> 0 | Y33: =E33*H33*(1-I33)*$Z$11*(1-$Z$10) -> 0 | Z33: =Y33-E33*F33*$Z$11 -> 0
B34: =IFERROR(VLOOKUP(A34,Mapping!$A:$F,2,FALSE),"") | C34: =IFERROR(VLOOKUP(A34,Mapping!$A:$F,3,FALSE),"") | F34: =IFERROR(VLOOKUP(A34,Mapping!$A:$F,4,FALSE),0) -> 0 | G34: =E34*F34 -> 0 | H34: =IFERROR(VLOOKUP(A34,Mapping!$A:$F,5,FALSE),0) -> 0 | J34: =IFERROR(VLOOKUP(A34,Mapping!$A:$F,6,FALSE),0) -> 0 | K34: =J34*(1-I34) -> 0 | L34: =IFERROR(J34-K34,"") -> 0 | M34: =E34*H34*(1-I34)*$N$11*(1-$N$10) -> 0 | N34: =M34-E34*F34*$N$11 -> 0 | O34: =E34*H34*(1-I34)*$P$11*(1-$P$10) -> 0 | P34: =O34-E34*F34*$P$11 -> 0 | Q34: =E34*H34*(1-I34)*$R$11*(1-$R$10) -> 0 | R34: =Q34-E34*F34*$R$11 -> 0 | S34: =E34*H34*(1-I34)*$T$11*(1-$T$10) -> 0 | T34: =S34-E34*F34*$T$11 -> 0 | U34: =E34*H34*(1-I34)*$V$11*(1-$V$10) -> 0 | V34: =U34-E34*F34*$V$11 -> 0 | W34: =E34*H34*(1-I34)*$X$11*(1-$X$10) -> 0 | X34: =W34-E34*F34*$X$11 -> 0 | Y34: =E34*H34*(1-I34)*$Z$11*(1-$Z$10) -> 0 | Z34: =Y34-E34*F34*$Z$11 -> 0
B35: =IFERROR(VLOOKUP(A35,Mapping!$A:$F,2,FALSE),"") | C35: =IFERROR(VLOOKUP(A35,Mapping!$A:$F,3,FALSE),"") | F35: =IFERROR(VLOOKUP(A35,Mapping!$A:$F,4,FALSE),0) -> 0 | G35: =E35*F35 -> 0 | H35: =IFERROR(VLOOKUP(A35,Mapping!$A:$F,5,FALSE),0) -> 0 | J35: =IFERROR(VLOOKUP(A35,Mapping!$A:$F,6,FALSE),0) -> 0 | K35: =J35*(1-I35) -> 0 | L35: =IFERROR(J35-K35,"") -> 0 | M35: =E35*H35*(1-I35)*$N$11*(1-$N$10) -> 0 | N35: =M35-E35*F35*$N$11 -> 0 | O35: =E35*H35*(1-I35)*$P$11*(1-$P$10) -> 0 | P35: =O35-E35*F35*$P$11 -> 0 | Q35: =E35*H35*(1-I35)*$R$11*(1-$R$10) -> 0 | R35: =Q35-E35*F35*$R$11 -> 0 | S35: =E35*H35*(1-I35)*$T$11*(1-$T$10) -> 0 | T35: =S35-E35*F35*$T$11 -> 0 | U35: =E35*H35*(1-I35)*$V$11*(1-$V$10) -> 0 | V35: =U35-E35*F35*$V$11 -> 0 | W35: =E35*H35*(1-I35)*$X$11*(1-$X$10) -> 0 | X35: =W35-E35*F35*$X$11 -> 0 | Y35: =E35*H35*(1-I35)*$Z$11*(1-$Z$10) -> 0 | Z35: =Y35-E35*F35*$Z$11 -> 0
B36: =IFERROR(VLOOKUP(A36,Mapping!$A:$F,2,FALSE),"") | C36: =IFERROR(VLOOKUP(A36,Mapping!$A:$F,3,FALSE),"") | F36: =IFERROR(VLOOKUP(A36,Mapping!$A:$F,4,FALSE),0) -> 0 | G36: =E36*F36 -> 0 | H36: =IFERROR(VLOOKUP(A36,Mapping!$A:$F,5,FALSE),0) -> 0 | J36: =IFERROR(VLOOKUP(A36,Mapping!$A:$F,6,FALSE),0) -> 0 | K36: =J36*(1-I36) -> 0 | L36: =IFERROR(J36-K36,"") -> 0 | M36: =E36*H36*(1-I36)*$N$11*(1-$N$10) -> 0 | N36: =M36-E36*F36*$N$11 -> 0 | O36: =E36*H36*(1-I36)*$P$11*(1-$P$10) -> 0 | P36: =O36-E36*F36*$P$11 -> 0 | Q36: =E36*H36*(1-I36)*$R$11*(1-$R$10) -> 0 | R36: =Q36-E36*F36*$R$11 -> 0 | S36: =E36*H36*(1-I36)*$T$11*(1-$T$10) -> 0 | T36: =S36-E36*F36*$T$11 -> 0 | U36: =E36*H36*(1-I36)*$V$11*(1-$V$10) -> 0 | V36: =U36-E36*F36*$V$11 -> 0 | W36: =E36*H36*(1-I36)*$X$11*(1-$X$10) -> 0 | X36: =W36-E36*F36*$X$11 -> 0 | Y36: =E36*H36*(1-I36)*$Z$11*(1-$Z$10) -> 0 | Z36: =Y36-E36*F36*$Z$11 -> 0
A39: PREMIUM
A40: Nombre d'offres
A41: Nombre de produits | B41: =SUM(E53:E65) -> 0
M42: RETAIL | S42: INSTITUT | AB42: Retail + Institut
M44: Ambassadeur | O44: Compagnon | Q44: Challenger | S44: Rose | U44: Prunelier | W44: Anthylide | Y44: Calendula | AB44: Total
M45: % Offres | O45: % Offres | Q45: % Offres | S45: % Offres | U45: % Offres | W45: % Offres
M46: Remise | N46: 0.17 | O46: Remise | P46: 0.13 | Q46: Remise | R46: 0.08 | S46: Remise | T46: 0.325 | U46: Remise | V46: 0.3 | W46: Remise | X46: 0.28 | Y46: Remise | Z46: 0.25
M47: Nb Offres | N47: =N45*$B$4 -> 0 | O47: Nb Offres | P47: =P45*$B$4 -> 0 | Q47: Nb Offres | R47: =R45*$B$4 -> 0 | S47: Nb Offres | T47: =T45*$B$4 -> 0 | U47: Nb Offres | V47: =V45*$B$4 -> 0 | W47: Nb Offres | X47: =X45*$B$4 -> 0 | Y47: Nb Offres | Z47: =Z45*$B$4 -> 0
E48: Pdt dans offre | F48: Coût achat unitaire | G48: Coûts achats total | H48: Tarif revendeur unitaire | I48: Remise additionnelle | J48: PPC | K48: PPC Remisé | L48: Montant BRI | M48: CA | N48: Marges | O48: CA | P48: Marges | Q48: CA | R48: Marges | S48: CA | T48: Marges | U48: CA | V48: Marges | W48: CA | X48: Marges | Y48: CA | Z48: Marges | AB48: Nbrs Offres planifiées | AC48: CA | AD48: Marges
...

Sheet Mapping
A1: Code article | B1: Libellé article | C1: Code à barres (EAN) | D1: Coût achat unitaire | E1: Tarif revendeur unitaire | F1: PPC
A2: 1010101 | B2: Crème Purifiante pour le Visage - 50 ml | C2: 4020829005181 | D2: 3.92 | E2: 10.58 | F2: 18
A3: 1010102 | B3: Lait Démaquillant et Nettoyant - 145 ml | C3: 4020829006041 | D3: 6.55 | E3: 17.06 | F3: 29
A4: 1010110 | B4: Démaquillant pour les Yeux - 75 ml | C4: 4020829063143 | D4: 6.08 | E4: 16.47 | F4: 28
A5: 1010115 | B5: Lait Démaquillant et Nettoyant - 30 ml | C5: 4020829066441 | D5: 2.47 | E5: 0 | F5: 0
A6: 1010116 | B6: Baume Lacté Nettoyant - 75 ml | C6: 4020829094048 | D6: 4.84 | E6: 12.94 | F6: 22
A7: 1010120 | B7: Baume Lacté Nettoyant - 20 ml | C7: 4020829101838 | D7: 1.61 | E7: 0 | F7: 0
A8: 1010121 | B8: Crème Purifiante pour le Visage - 20 ml | C8: 4020829101821 | D8: 1.63 | E8: 0 | F8: 0
A9: 1010122 | B9: Baume Lacté Nettoyant 20ml Édition spéciale 2025 | C9: 4020829111776 | D9: 0 | E9: 0 | F9: 0
A10: 1010201 | B10: Lotion Tonifiante - 100 ml | C10: 4020829005235 | D10: 6.72 | E10: 18.24 | F10: 31
A11: 1010202 | B11: Lotion Clarifiante - 100 ml | C11: 4020829005297 | D11: 7.06 | E11: 18.24 | F11: 31
A12: 1010205 | B12: Lotion Tonifiante - 30 ml | C12: 4020829066465 | D12: 2.44 | E12: 0 | F12: 9.2
A13: 1010206 | B13: Lotion Clarifiante - 30 ml | C13: 4020829114241 | D13: 2.64 | E13: 0 | F13: 0
... A63: 1011050 | B63: Coffret Rituel de Rose* DLV 01/2026* (copie) | C63: 1011050999999 | D63: 11.86 | E63: 15.8 | F63: 39.5
A64: 1011054 | B64: Coffret de noël rituel soin 2025 (copie) | D64: 11.95 | E64: 15.8 | F64: 39.5
A65: 1011055 | B65: Mon rituel Apaisant 2026 | C65: 3770026497562 | D65: 5.34 | E65: 10.53 | F65: 17.9
A66: 1011056 | B66: Mon rituel Éclat 2026 | C66: 3770026497579 | D66: 5.38 | E66: 10.53 | F66: 17.9
A67: 1011057 | B67: Coffret Les Essentiels Éclat 2026 | C67: 3770026497586 | D67: 6.35 | E67: 10.58 | F67: 18
A68: 1011058 | B68: Duo Baume Lacté Nettoyant 2026 | C68: 3770026497593 | D68: 9.58 | E68: 19.41 | F68: 33
A69: 1011059 | B69: Coffret Noël 2026 Rituel de Roses | C69: 3770026497623 | D69: 12.45 | E69: 27.59 | F69: 46.9
A70: 1011060 | B70: Coffret Noël 2026 Rituel Éclat | C70: 3770026497630 | D70: 10.72 | E70: 17.59 | F70: 29.9
A71: 1011061 | B71: Coffret Noël 2026 Duo Mains & Lèvres | C71: 3770026497654 | D71: 4.31 | E71: 8.76 | F71: 14.9
A72: 1011062 | B72: Calendrier de l’Avent 2026 | D72: 43.36 | E72: 0 | F72: 0
A73: 1011063 | B73: Duo Stick Éclat des Lèvres 2026 | C73: 3770026497609 | D73: 6.22 | E73: 10.23 | F73: 17.9
A74: 1020101 | B74: Lait pour le Corps Régénérant - 150 ml | C74: 4020829008410 | D74: 10.23 | E74: 26.12 | F74: 44.4
A75: 1020102 | B75: Crème pour les Mains - Régénérant - 50 ml | C75: 4020829049666 | D75: 6.55 | E75: 17.35 | F75: 29.5
A76: 1020107 | B76: Lait pour le Corps - Régénérant - 150 ml | C76: 4020829103160 | D76: 10.34 | E76: 26.12 | F76: 44.4
A77: 1020202 | B77: Sérum Jour/Nuit - Régénérant - 30 ml | C77: 4020829103115 | D77: 15.84 | E77: 41.12 | F77: 69.9
A78: 1020301 | B78: Crème de Jour - Régénérant - 40 ml | C78: 4020829007383 | D78: 14.8 | E78: 38.53 | F78: 65.5
A79: 1020302 | B79: Crème Cou et Décolleté - Régénérant - 40 ml | C79: 4020829008366 | D79: 13.77 | E79: 35.88 | F79: 61
A80: 1020310 | B80: Crème de Jour Eclat du Teint - Régénérant - 40 ml | C80: 4020829060999 | D80: 16.22 | E80: 41.12 | F80: 69.9
A81: 1020401 | B81: Crème Contour des Yeux - Régénérant - 15 ml | C81: 4020829013919 | D81: 15.34 | E81: 39.71 | F81: 67.5
A82: 1020704 | B82: Sérum Huile Régénérant Intensif - 20 ml | C82: 4020829074101 | D82: 0 | E82: 46.18 | F82: 78.5
A83: 1020717 | B83: Sérum Contour des Yeux - Régénérant Intensif -15 ml | C83: 4020829101067 | D83: 17.64 | E83: 44.12 | F83: 75
A84: 1020718 | B84: Sérum de Nuit - Régénérant Intensif - 30 ml | C84: 4020829101111 | D84: 18.28 | E84: 46.76 | F84: 79.5
... A116: 1030504 | B116: Après-Soleil 30ml | C116: 4020829087446 | D116: 2.16 | E116: 0 | F116: 28.92
A117: 1030601 | B117: Poudre de Soie - 50 g | D117: 6.99 | E117: 17.94 | F117: 30.5
A118: 1030602 | B118: Poudre de Soie - 50 g - DLV -20% | C118: 4020829005631 | D118: 0 | E118: 14.35 | F118: 0
A119: 1030703 | B119: Déodorant Rose - 50 ml | C119: 4020829025332 | D119: 4.13 | E119: 10.41 | F119: 17.7
A120: 1030704 | B120: Déodorant Sauge Menthe - 50 ml | C120: 4020829025370 | D120: 3.78 | E120: 9.47 | F120: 16.1
...

Sheet Synthèse logistique
